# Django log file for SFD backend
# This file will be written by the Django logging system.
INFO 2025-08-21 17:44:37,876 autoreload 7084 14468 Watching for file changes with StatReloader
WARNING 2025-08-21 17:45:09,202 log 7084 12548 Not Found: /api/v1/master/wrapper/
WARNING 2025-08-21 17:45:09,203 basehttp 7084 12548 "POST /api/v1/master/wrapper/ HTTP/1.1" 404 2396
ERROR 2025-08-21 17:45:25,248 log 7084 12548 Internal Server Error: /api/v1/sfd/wrapper/
Traceback (most recent call last):
  File "C:\Users\sthombare\AppData\Local\Programs\Python\Python312\Lib\site-packages\django\db\backends\utils.py", line 105, in _execute
    return self.cursor.execute(sql, params)
           ^^^^^^^^^^^^^^^^^^^^^^^^^^^^^^^^
psycopg2.errors.DatatypeMismatch: argument of WHERE must be type boolean, not type smallint
LINE 1: ..._add"."is_active" FROM "vw_sfd_section_add" WHERE "vw_sfd_se...
                                                             ^


The above exception was the direct cause of the following exception:

Traceback (most recent call last):
  File "C:\Users\sthombare\AppData\Local\Programs\Python\Python312\Lib\site-packages\django\core\handlers\exception.py", line 55, in inner
    response = get_response(request)
               ^^^^^^^^^^^^^^^^^^^^^
  File "C:\Users\sthombare\AppData\Local\Programs\Python\Python312\Lib\site-packages\django\core\handlers\base.py", line 197, in _get_response
    response = wrapped_callback(request, *callback_args, **callback_kwargs)
               ^^^^^^^^^^^^^^^^^^^^^^^^^^^^^^^^^^^^^^^^^^^^^^^^^^^^^^^^^^^^
  File "C:\Users\sthombare\AppData\Local\Programs\Python\Python312\Lib\site-packages\django\views\decorators\csrf.py", line 65, in _view_wrapper
    return view_func(request, *args, **kwargs)
           ^^^^^^^^^^^^^^^^^^^^^^^^^^^^^^^^^^^
  File "C:\Users\sthombare\AppData\Local\Programs\Python\Python312\Lib\site-packages\django\views\generic\base.py", line 105, in view
    return self.dispatch(request, *args, **kwargs)
           ^^^^^^^^^^^^^^^^^^^^^^^^^^^^^^^^^^^^^^^
  File "C:\Users\sthombare\AppData\Local\Programs\Python\Python312\Lib\site-packages\rest_framework\views.py", line 515, in dispatch
    response = self.handle_exception(exc)
               ^^^^^^^^^^^^^^^^^^^^^^^^^^
  File "C:\Users\sthombare\AppData\Local\Programs\Python\Python312\Lib\site-packages\rest_framework\views.py", line 475, in handle_exception
    self.raise_uncaught_exception(exc)
  File "C:\Users\sthombare\AppData\Local\Programs\Python\Python312\Lib\site-packages\rest_framework\views.py", line 486, in raise_uncaught_exception
    raise exc
  File "C:\Users\sthombare\AppData\Local\Programs\Python\Python312\Lib\site-packages\rest_framework\views.py", line 512, in dispatch
    response = handler(request, *args, **kwargs)
               ^^^^^^^^^^^^^^^^^^^^^^^^^^^^^^^^^
  File "D:\Phoenix\Defense_POC\POC4\services\SFD\backend\apps\sfd\views.py", line 533, in post
    return crud_list(request.user, table_name)
           ^^^^^^^^^^^^^^^^^^^^^^^^^^^^^^^^^^^
  File "D:\Phoenix\Defense_POC\POC4\services\SFD\backend\apps\sfd\views.py", line 98, in crud_list
    'data': serializer.data
            ^^^^^^^^^^^^^^^
  File "C:\Users\sthombare\AppData\Local\Programs\Python\Python312\Lib\site-packages\rest_framework\serializers.py", line 797, in data
    ret = super().data
          ^^^^^^^^^^^^
  File "C:\Users\sthombare\AppData\Local\Programs\Python\Python312\Lib\site-packages\rest_framework\serializers.py", line 251, in data
    self._data = self.to_representation(self.instance)
                 ^^^^^^^^^^^^^^^^^^^^^^^^^^^^^^^^^^^^^
  File "C:\Users\sthombare\AppData\Local\Programs\Python\Python312\Lib\site-packages\rest_framework\serializers.py", line 716, in to_representation
    self.child.to_representation(item) for item in iterable
                                                   ^^^^^^^^
  File "C:\Users\sthombare\AppData\Local\Programs\Python\Python312\Lib\site-packages\django\db\models\query.py", line 384, in __iter__
    self._fetch_all()
  File "C:\Users\sthombare\AppData\Local\Programs\Python\Python312\Lib\site-packages\django\db\models\query.py", line 1949, in _fetch_all
    self._result_cache = list(self._iterable_class(self))
                         ^^^^^^^^^^^^^^^^^^^^^^^^^^^^^^^^
  File "C:\Users\sthombare\AppData\Local\Programs\Python\Python312\Lib\site-packages\django\db\models\query.py", line 91, in __iter__
    results = compiler.execute_sql(
              ^^^^^^^^^^^^^^^^^^^^^
  File "C:\Users\sthombare\AppData\Local\Programs\Python\Python312\Lib\site-packages\django\db\models\sql\compiler.py", line 1623, in execute_sql
    cursor.execute(sql, params)
  File "C:\Users\sthombare\AppData\Local\Programs\Python\Python312\Lib\site-packages\django\db\backends\utils.py", line 122, in execute
    return super().execute(sql, params)
           ^^^^^^^^^^^^^^^^^^^^^^^^^^^^
  File "C:\Users\sthombare\AppData\Local\Programs\Python\Python312\Lib\site-packages\django\db\backends\utils.py", line 79, in execute
    return self._execute_with_wrappers(
           ^^^^^^^^^^^^^^^^^^^^^^^^^^^^
  File "C:\Users\sthombare\AppData\Local\Programs\Python\Python312\Lib\site-packages\django\db\backends\utils.py", line 92, in _execute_with_wrappers
    return executor(sql, params, many, context)
           ^^^^^^^^^^^^^^^^^^^^^^^^^^^^^^^^^^^^
  File "C:\Users\sthombare\AppData\Local\Programs\Python\Python312\Lib\site-packages\django\db\backends\utils.py", line 100, in _execute
    with self.db.wrap_database_errors:
         ^^^^^^^^^^^^^^^^^^^^^^^^^^^^
  File "C:\Users\sthombare\AppData\Local\Programs\Python\Python312\Lib\site-packages\django\db\utils.py", line 91, in __exit__
    raise dj_exc_value.with_traceback(traceback) from exc_value
  File "C:\Users\sthombare\AppData\Local\Programs\Python\Python312\Lib\site-packages\django\db\backends\utils.py", line 105, in _execute
    return self.cursor.execute(sql, params)
           ^^^^^^^^^^^^^^^^^^^^^^^^^^^^^^^^
django.db.utils.ProgrammingError: argument of WHERE must be type boolean, not type smallint
LINE 1: ..._add"."is_active" FROM "vw_sfd_section_add" WHERE "vw_sfd_se...
                                                             ^

ERROR 2025-08-21 17:45:25,262 basehttp 7084 12548 "POST /api/v1/sfd/wrapper/ HTTP/1.1" 500 173180
INFO 2025-08-21 17:47:40,465 autoreload 7084 14468 D:\Phoenix\Defense_POC\POC4\services\SFD\backend\apps\sfd\models.py changed, reloading.
INFO 2025-08-21 17:47:45,663 autoreload 31576 8780 Watching for file changes with StatReloader
ERROR 2025-08-21 17:47:51,433 log 31576 28624 Internal Server Error: /api/v1/sfd/wrapper/
Traceback (most recent call last):
  File "C:\Users\sthombare\AppData\Local\Programs\Python\Python312\Lib\site-packages\django\core\handlers\exception.py", line 55, in inner
    response = get_response(request)
               ^^^^^^^^^^^^^^^^^^^^^
  File "C:\Users\sthombare\AppData\Local\Programs\Python\Python312\Lib\site-packages\django\core\handlers\base.py", line 197, in _get_response
    response = wrapped_callback(request, *callback_args, **callback_kwargs)
               ^^^^^^^^^^^^^^^^^^^^^^^^^^^^^^^^^^^^^^^^^^^^^^^^^^^^^^^^^^^^
  File "C:\Users\sthombare\AppData\Local\Programs\Python\Python312\Lib\site-packages\django\views\decorators\csrf.py", line 65, in _view_wrapper
    return view_func(request, *args, **kwargs)
           ^^^^^^^^^^^^^^^^^^^^^^^^^^^^^^^^^^^
  File "C:\Users\sthombare\AppData\Local\Programs\Python\Python312\Lib\site-packages\django\views\generic\base.py", line 105, in view
    return self.dispatch(request, *args, **kwargs)
           ^^^^^^^^^^^^^^^^^^^^^^^^^^^^^^^^^^^^^^^
  File "C:\Users\sthombare\AppData\Local\Programs\Python\Python312\Lib\site-packages\rest_framework\views.py", line 515, in dispatch
    response = self.handle_exception(exc)
               ^^^^^^^^^^^^^^^^^^^^^^^^^^
  File "C:\Users\sthombare\AppData\Local\Programs\Python\Python312\Lib\site-packages\rest_framework\views.py", line 475, in handle_exception
    self.raise_uncaught_exception(exc)
  File "C:\Users\sthombare\AppData\Local\Programs\Python\Python312\Lib\site-packages\rest_framework\views.py", line 486, in raise_uncaught_exception
    raise exc
  File "C:\Users\sthombare\AppData\Local\Programs\Python\Python312\Lib\site-packages\rest_framework\views.py", line 512, in dispatch
    response = handler(request, *args, **kwargs)
               ^^^^^^^^^^^^^^^^^^^^^^^^^^^^^^^^^
  File "D:\Phoenix\Defense_POC\POC4\services\SFD\backend\apps\sfd\views.py", line 533, in post
    return crud_list(request.user, table_name)
           ^^^^^^^^^^^^^^^^^^^^^^^^^^^^^^^^^^^
  File "D:\Phoenix\Defense_POC\POC4\services\SFD\backend\apps\sfd\views.py", line 98, in crud_list
    'data': serializer.data
            ^^^^^^^^^^^^^^^
  File "C:\Users\sthombare\AppData\Local\Programs\Python\Python312\Lib\site-packages\rest_framework\serializers.py", line 797, in data
    ret = super().data
          ^^^^^^^^^^^^
  File "C:\Users\sthombare\AppData\Local\Programs\Python\Python312\Lib\site-packages\rest_framework\serializers.py", line 251, in data
    self._data = self.to_representation(self.instance)
                 ^^^^^^^^^^^^^^^^^^^^^^^^^^^^^^^^^^^^^
  File "C:\Users\sthombare\AppData\Local\Programs\Python\Python312\Lib\site-packages\rest_framework\serializers.py", line 716, in to_representation
    self.child.to_representation(item) for item in iterable
    ^^^^^^^^^^^^^^^^^^^^^^^^^^^^^^^^^^
  File "C:\Users\sthombare\AppData\Local\Programs\Python\Python312\Lib\site-packages\rest_framework\serializers.py", line 540, in to_representation
    ret[field.field_name] = field.to_representation(attribute)
                            ^^^^^^^^^^^^^^^^^^^^^^^^^^^^^^^^^^
  File "C:\Users\sthombare\AppData\Local\Programs\Python\Python312\Lib\site-packages\rest_framework\fields.py", line 921, in to_representation
    return int(value)
           ^^^^^^^^^^
ValueError: invalid literal for int() with base 10: 'SE-00002'
ERROR 2025-08-21 17:47:51,442 basehttp 31576 28624 "POST /api/v1/sfd/wrapper/ HTTP/1.1" 500 136927
INFO 2025-08-21 17:49:21,585 autoreload 31576 8780 D:\Phoenix\Defense_POC\POC4\services\SFD\backend\apps\sfd\models.py changed, reloading.
INFO 2025-08-21 17:49:26,821 autoreload 1988 33624 Watching for file changes with StatReloader
INFO 2025-08-21 17:49:28,802 autoreload 1988 33624 D:\Phoenix\Defense_POC\POC4\services\SFD\backend\apps\sfd\models.py changed, reloading.
INFO 2025-08-21 17:49:33,963 autoreload 24572 17476 Watching for file changes with StatReloader
ERROR 2025-08-21 17:49:38,549 log 24572 9480 Internal Server Error: /api/v1/sfd/wrapper/
Traceback (most recent call last):
  File "C:\Users\sthombare\AppData\Local\Programs\Python\Python312\Lib\site-packages\django\db\backends\utils.py", line 105, in _execute
    return self.cursor.execute(sql, params)
           ^^^^^^^^^^^^^^^^^^^^^^^^^^^^^^^^
psycopg2.errors.UndefinedColumn: column vw_sfd_section_add.id does not exist
LINE 1: SELECT "vw_sfd_section_add"."id", "vw_sfd_section_add"."sect...
               ^


The above exception was the direct cause of the following exception:

Traceback (most recent call last):
  File "C:\Users\sthombare\AppData\Local\Programs\Python\Python312\Lib\site-packages\django\core\handlers\exception.py", line 55, in inner
    response = get_response(request)
               ^^^^^^^^^^^^^^^^^^^^^
  File "C:\Users\sthombare\AppData\Local\Programs\Python\Python312\Lib\site-packages\django\core\handlers\base.py", line 197, in _get_response
    response = wrapped_callback(request, *callback_args, **callback_kwargs)
               ^^^^^^^^^^^^^^^^^^^^^^^^^^^^^^^^^^^^^^^^^^^^^^^^^^^^^^^^^^^^
  File "C:\Users\sthombare\AppData\Local\Programs\Python\Python312\Lib\site-packages\django\views\decorators\csrf.py", line 65, in _view_wrapper
    return view_func(request, *args, **kwargs)
           ^^^^^^^^^^^^^^^^^^^^^^^^^^^^^^^^^^^
  File "C:\Users\sthombare\AppData\Local\Programs\Python\Python312\Lib\site-packages\django\views\generic\base.py", line 105, in view
    return self.dispatch(request, *args, **kwargs)
           ^^^^^^^^^^^^^^^^^^^^^^^^^^^^^^^^^^^^^^^
  File "C:\Users\sthombare\AppData\Local\Programs\Python\Python312\Lib\site-packages\rest_framework\views.py", line 515, in dispatch
    response = self.handle_exception(exc)
               ^^^^^^^^^^^^^^^^^^^^^^^^^^
  File "C:\Users\sthombare\AppData\Local\Programs\Python\Python312\Lib\site-packages\rest_framework\views.py", line 475, in handle_exception
    self.raise_uncaught_exception(exc)
  File "C:\Users\sthombare\AppData\Local\Programs\Python\Python312\Lib\site-packages\rest_framework\views.py", line 486, in raise_uncaught_exception
    raise exc
  File "C:\Users\sthombare\AppData\Local\Programs\Python\Python312\Lib\site-packages\rest_framework\views.py", line 512, in dispatch
    response = handler(request, *args, **kwargs)
               ^^^^^^^^^^^^^^^^^^^^^^^^^^^^^^^^^
  File "D:\Phoenix\Defense_POC\POC4\services\SFD\backend\apps\sfd\views.py", line 533, in post
    return crud_list(request.user, table_name)
           ^^^^^^^^^^^^^^^^^^^^^^^^^^^^^^^^^^^
  File "D:\Phoenix\Defense_POC\POC4\services\SFD\backend\apps\sfd\views.py", line 98, in crud_list
    'data': serializer.data
            ^^^^^^^^^^^^^^^
  File "C:\Users\sthombare\AppData\Local\Programs\Python\Python312\Lib\site-packages\rest_framework\serializers.py", line 797, in data
    ret = super().data
          ^^^^^^^^^^^^
  File "C:\Users\sthombare\AppData\Local\Programs\Python\Python312\Lib\site-packages\rest_framework\serializers.py", line 251, in data
    self._data = self.to_representation(self.instance)
                 ^^^^^^^^^^^^^^^^^^^^^^^^^^^^^^^^^^^^^
  File "C:\Users\sthombare\AppData\Local\Programs\Python\Python312\Lib\site-packages\rest_framework\serializers.py", line 716, in to_representation
    self.child.to_representation(item) for item in iterable
                                                   ^^^^^^^^
  File "C:\Users\sthombare\AppData\Local\Programs\Python\Python312\Lib\site-packages\django\db\models\query.py", line 384, in __iter__
    self._fetch_all()
  File "C:\Users\sthombare\AppData\Local\Programs\Python\Python312\Lib\site-packages\django\db\models\query.py", line 1949, in _fetch_all
    self._result_cache = list(self._iterable_class(self))
                         ^^^^^^^^^^^^^^^^^^^^^^^^^^^^^^^^
  File "C:\Users\sthombare\AppData\Local\Programs\Python\Python312\Lib\site-packages\django\db\models\query.py", line 91, in __iter__
    results = compiler.execute_sql(
              ^^^^^^^^^^^^^^^^^^^^^
  File "C:\Users\sthombare\AppData\Local\Programs\Python\Python312\Lib\site-packages\django\db\models\sql\compiler.py", line 1623, in execute_sql
    cursor.execute(sql, params)
  File "C:\Users\sthombare\AppData\Local\Programs\Python\Python312\Lib\site-packages\django\db\backends\utils.py", line 122, in execute
    return super().execute(sql, params)
           ^^^^^^^^^^^^^^^^^^^^^^^^^^^^
  File "C:\Users\sthombare\AppData\Local\Programs\Python\Python312\Lib\site-packages\django\db\backends\utils.py", line 79, in execute
    return self._execute_with_wrappers(
           ^^^^^^^^^^^^^^^^^^^^^^^^^^^^
  File "C:\Users\sthombare\AppData\Local\Programs\Python\Python312\Lib\site-packages\django\db\backends\utils.py", line 92, in _execute_with_wrappers
    return executor(sql, params, many, context)
           ^^^^^^^^^^^^^^^^^^^^^^^^^^^^^^^^^^^^
  File "C:\Users\sthombare\AppData\Local\Programs\Python\Python312\Lib\site-packages\django\db\backends\utils.py", line 100, in _execute
    with self.db.wrap_database_errors:
         ^^^^^^^^^^^^^^^^^^^^^^^^^^^^
  File "C:\Users\sthombare\AppData\Local\Programs\Python\Python312\Lib\site-packages\django\db\utils.py", line 91, in __exit__
    raise dj_exc_value.with_traceback(traceback) from exc_value
  File "C:\Users\sthombare\AppData\Local\Programs\Python\Python312\Lib\site-packages\django\db\backends\utils.py", line 105, in _execute
    return self.cursor.execute(sql, params)
           ^^^^^^^^^^^^^^^^^^^^^^^^^^^^^^^^
django.db.utils.ProgrammingError: column vw_sfd_section_add.id does not exist
LINE 1: SELECT "vw_sfd_section_add"."id", "vw_sfd_section_add"."sect...
               ^

ERROR 2025-08-21 17:49:38,562 basehttp 24572 9480 "POST /api/v1/sfd/wrapper/ HTTP/1.1" 500 172401
INFO 2025-08-21 17:49:53,809 autoreload 24572 17476 D:\Phoenix\Defense_POC\POC4\services\SFD\backend\apps\sfd\models.py changed, reloading.
INFO 2025-08-21 17:49:58,973 autoreload 18932 18748 Watching for file changes with StatReloader
INFO 2025-08-21 17:57:06,989 autoreload 18932 18748 D:\Phoenix\Defense_POC\POC4\services\SFD\backend\apps\sfd\models.py changed, reloading.
INFO 2025-08-21 17:57:12,192 autoreload 22208 4212 Watching for file changes with StatReloader
INFO 2025-08-21 17:57:16,436 autoreload 22208 4212 D:\Phoenix\Defense_POC\POC4\services\SFD\backend\apps\sfd\models.py changed, reloading.
INFO 2025-08-21 17:57:21,599 autoreload 15284 34156 Watching for file changes with StatReloader
INFO 2025-08-21 17:57:23,239 basehttp 15284 20300 "POST /api/v1/sfd/wrapper/ HTTP/1.1" 200 3743
INFO 2025-08-21 18:54:36,491 autoreload 15284 34156 D:\Phoenix\Defense_POC\POC4\services\SFD\backend\apps\sfd\models.py changed, reloading.
INFO 2025-08-21 18:54:44,088 autoreload 34280 33768 Watching for file changes with StatReloader
WARNING 2025-08-21 18:57:46,845 log 34280 19240 Unauthorized: /api/v1/sfd/wrapper/
WARNING 2025-08-21 18:57:46,845 basehttp 34280 19240 "POST /api/v1/sfd/wrapper/ HTTP/1.1" 401 172
WARNING 2025-08-21 18:58:23,205 log 34280 19240 Bad Request: /api/v1/sfd/wrapper/
WARNING 2025-08-21 18:58:23,205 basehttp 34280 19240 "POST /api/v1/sfd/wrapper/ HTTP/1.1" 400 61
INFO 2025-08-21 19:00:10,308 autoreload 2968 21192 Watching for file changes with StatReloader
