INFO 2025-08-15 13:37:20,995 autoreload 8888 36788 Watching for file changes with StatReloader
INFO 2025-08-15 13:38:46,197 autoreload 21328 23092 Watching for file changes with StatReloader
INFO 2025-08-15 13:42:34,951 autoreload 21456 29000 Watching for file changes with StatReloader
INFO 2025-08-15 13:47:26,006 autoreload 35568 34540 Watching for file changes with StatReloader
INFO 2025-08-15 13:48:40,116 autoreload 33908 28916 Watching for file changes with StatReloader
INFO 2025-08-15 18:08:35,721 autoreload 13388 3200 Watching for file changes with StatReloader
WARNING 2025-08-15 18:08:56,886 log 13388 40084 Not Found: /
WARNING 2025-08-15 18:08:56,887 basehttp 13388 40084 "GET / HTTP/1.1" 404 2976
WARNING 2025-08-15 18:09:00,534 log 13388 40084 Not Found: /favicon.ico
WARNING 2025-08-15 18:09:00,534 basehttp 13388 40084 "GET /favicon.ico HTTP/1.1" 404 3027
WARNING 2025-08-15 18:15:34,328 log 13388 24792 Not Found: /api/v1/auth/
WARNING 2025-08-15 18:15:34,328 basehttp 13388 24792 "GET /api/v1/auth/ HTTP/1.1" 404 4224
INFO 2025-08-15 18:15:44,023 basehttp 13388 24792 "GET /api/v1/auth/login HTTP/1.1" 301 0
ERROR 2025-08-15 18:15:44,549 log 13388 43448 Internal Server Error: /api/v1/auth/login/
Traceback (most recent call last):
  File "D:\OneDrive - Xcaliber Infotech\WORKSPACE\Products\Project-NAVY\navy\Lib\site-packages\redis\connection.py", line 1526, in get_connection
    connection = self._available_connections.pop()
                 ^^^^^^^^^^^^^^^^^^^^^^^^^^^^^^^^^
IndexError: pop from empty list

During handling of the above exception, another exception occurred:

Traceback (most recent call last):
  File "D:\OneDrive - Xcaliber Infotech\WORKSPACE\Products\Project-NAVY\navy\Lib\site-packages\django\core\handlers\exception.py", line 55, in inner
    response = get_response(request)
               ^^^^^^^^^^^^^^^^^^^^^
  File "D:\OneDrive - Xcaliber Infotech\WORKSPACE\Products\Project-NAVY\navy\Lib\site-packages\django\core\handlers\base.py", line 197, in _get_response
    response = wrapped_callback(request, *callback_args, **callback_kwargs)
               ^^^^^^^^^^^^^^^^^^^^^^^^^^^^^^^^^^^^^^^^^^^^^^^^^^^^^^^^^^^^
  File "D:\OneDrive - Xcaliber Infotech\WORKSPACE\Products\Project-NAVY\navy\Lib\site-packages\django\views\decorators\csrf.py", line 65, in _view_wrapper
    return view_func(request, *args, **kwargs)
           ^^^^^^^^^^^^^^^^^^^^^^^^^^^^^^^^^^^
  File "D:\OneDrive - Xcaliber Infotech\WORKSPACE\Products\Project-NAVY\navy\Lib\site-packages\django\views\generic\base.py", line 105, in view
    return self.dispatch(request, *args, **kwargs)
           ^^^^^^^^^^^^^^^^^^^^^^^^^^^^^^^^^^^^^^^
  File "D:\OneDrive - Xcaliber Infotech\WORKSPACE\Products\Project-NAVY\navy\Lib\site-packages\rest_framework\views.py", line 515, in dispatch
    response = self.handle_exception(exc)
               ^^^^^^^^^^^^^^^^^^^^^^^^^^
  File "D:\OneDrive - Xcaliber Infotech\WORKSPACE\Products\Project-NAVY\navy\Lib\site-packages\rest_framework\views.py", line 475, in handle_exception
    self.raise_uncaught_exception(exc)
  File "D:\OneDrive - Xcaliber Infotech\WORKSPACE\Products\Project-NAVY\navy\Lib\site-packages\rest_framework\views.py", line 486, in raise_uncaught_exception
    raise exc
  File "D:\OneDrive - Xcaliber Infotech\WORKSPACE\Products\Project-NAVY\navy\Lib\site-packages\rest_framework\views.py", line 503, in dispatch
    self.initial(request, *args, **kwargs)
  File "D:\OneDrive - Xcaliber Infotech\WORKSPACE\Products\Project-NAVY\navy\Lib\site-packages\rest_framework\views.py", line 422, in initial
    self.check_throttles(request)
  File "D:\OneDrive - Xcaliber Infotech\WORKSPACE\Products\Project-NAVY\navy\Lib\site-packages\rest_framework\views.py", line 365, in check_throttles
    if not throttle.allow_request(request, self):
           ^^^^^^^^^^^^^^^^^^^^^^^^^^^^^^^^^^^^^
  File "D:\OneDrive - Xcaliber Infotech\WORKSPACE\Products\Project-NAVY\navy\Lib\site-packages\rest_framework\throttling.py", line 123, in allow_request
    self.history = self.cache.get(self.key, [])
                   ^^^^^^^^^^^^^^^^^^^^^^^^^^^^
  File "D:\OneDrive - Xcaliber Infotech\WORKSPACE\Products\Project-NAVY\navy\Lib\site-packages\django\core\cache\backends\redis.py", line 188, in get
    return self._cache.get(key, default)
           ^^^^^^^^^^^^^^^^^^^^^^^^^^^^^
  File "D:\OneDrive - Xcaliber Infotech\WORKSPACE\Products\Project-NAVY\navy\Lib\site-packages\django\core\cache\backends\redis.py", line 100, in get
    value = client.get(key)
            ^^^^^^^^^^^^^^^
  File "D:\OneDrive - Xcaliber Infotech\WORKSPACE\Products\Project-NAVY\navy\Lib\site-packages\redis\commands\core.py", line 1829, in get
    return self.execute_command("GET", name, keys=[name])
           ^^^^^^^^^^^^^^^^^^^^^^^^^^^^^^^^^^^^^^^^^^^^^^
  File "D:\OneDrive - Xcaliber Infotech\WORKSPACE\Products\Project-NAVY\navy\Lib\site-packages\redis\client.py", line 621, in execute_command
    return self._execute_command(*args, **options)
           ^^^^^^^^^^^^^^^^^^^^^^^^^^^^^^^^^^^^^^^
  File "D:\OneDrive - Xcaliber Infotech\WORKSPACE\Products\Project-NAVY\navy\Lib\site-packages\redis\client.py", line 627, in _execute_command
    conn = self.connection or pool.get_connection()
                              ^^^^^^^^^^^^^^^^^^^^^
  File "D:\OneDrive - Xcaliber Infotech\WORKSPACE\Products\Project-NAVY\navy\Lib\site-packages\redis\utils.py", line 195, in wrapper
    return func(*args, **kwargs)
           ^^^^^^^^^^^^^^^^^^^^^
  File "D:\OneDrive - Xcaliber Infotech\WORKSPACE\Products\Project-NAVY\navy\Lib\site-packages\redis\connection.py", line 1528, in get_connection
    connection = self.make_connection()
                 ^^^^^^^^^^^^^^^^^^^^^^
  File "D:\OneDrive - Xcaliber Infotech\WORKSPACE\Products\Project-NAVY\navy\Lib\site-packages\redis\connection.py", line 1574, in make_connection
    return self.connection_class(**self.connection_kwargs)
           ^^^^^^^^^^^^^^^^^^^^^^^^^^^^^^^^^^^^^^^^^^^^^^^
  File "D:\OneDrive - Xcaliber Infotech\WORKSPACE\Products\Project-NAVY\navy\Lib\site-packages\redis\connection.py", line 753, in __init__
    super().__init__(**kwargs)
TypeError: AbstractConnection.__init__() got an unexpected keyword argument 'CLIENT_CLASS'
ERROR 2025-08-15 18:15:44,569 basehttp 13388 43448 "GET /api/v1/auth/login/ HTTP/1.1" 500 157298
INFO 2025-08-15 18:18:32,093 basehttp 13388 5100 "GET /api/v1/auth/profile HTTP/1.1" 301 0
WARNING 2025-08-15 18:18:32,103 log 13388 35692 Unauthorized: /api/v1/auth/profile/
WARNING 2025-08-15 18:18:32,105 basehttp 13388 35692 "GET /api/v1/auth/profile/ HTTP/1.1" 401 58
ERROR 2025-08-15 18:22:27,513 log 13388 35692 Internal Server Error: /api/v1/auth/signup
Traceback (most recent call last):
  File "D:\OneDrive - Xcaliber Infotech\WORKSPACE\Products\Project-NAVY\navy\Lib\site-packages\django\core\handlers\exception.py", line 55, in inner
    response = get_response(request)
               ^^^^^^^^^^^^^^^^^^^^^
  File "D:\OneDrive - Xcaliber Infotech\WORKSPACE\Products\Project-NAVY\navy\Lib\site-packages\django\utils\deprecation.py", line 122, in __call__
    response = self.process_response(request, response)
               ^^^^^^^^^^^^^^^^^^^^^^^^^^^^^^^^^^^^^^^^
  File "D:\OneDrive - Xcaliber Infotech\WORKSPACE\Products\Project-NAVY\navy\Lib\site-packages\django\middleware\common.py", line 108, in process_response
    return self.response_redirect_class(self.get_full_path_with_slash(request))
                                        ^^^^^^^^^^^^^^^^^^^^^^^^^^^^^^^^^^^^^^
  File "D:\OneDrive - Xcaliber Infotech\WORKSPACE\Products\Project-NAVY\navy\Lib\site-packages\django\middleware\common.py", line 87, in get_full_path_with_slash
    raise RuntimeError(
RuntimeError: You called this URL via POST, but the URL doesn't end in a slash and you have APPEND_SLASH set. Django can't redirect to the slash URL while maintaining POST data. Change your form to point to 127.0.0.1:8000/api/v1/auth/signup/ (note the trailing slash), or set APPEND_SLASH=False in your Django settings.
ERROR 2025-08-15 18:22:27,519 basehttp 13388 35692 "POST /api/v1/auth/signup HTTP/1.1" 500 76925
ERROR 2025-08-15 18:23:19,472 log 13388 42864 Internal Server Error: /api/v1/auth/signup/
Traceback (most recent call last):
  File "D:\OneDrive - Xcaliber Infotech\WORKSPACE\Products\Project-NAVY\navy\Lib\site-packages\redis\connection.py", line 1526, in get_connection
    connection = self._available_connections.pop()
                 ^^^^^^^^^^^^^^^^^^^^^^^^^^^^^^^^^
IndexError: pop from empty list

During handling of the above exception, another exception occurred:

Traceback (most recent call last):
  File "D:\OneDrive - Xcaliber Infotech\WORKSPACE\Products\Project-NAVY\navy\Lib\site-packages\django\core\handlers\exception.py", line 55, in inner
    response = get_response(request)
               ^^^^^^^^^^^^^^^^^^^^^
  File "D:\OneDrive - Xcaliber Infotech\WORKSPACE\Products\Project-NAVY\navy\Lib\site-packages\django\core\handlers\base.py", line 197, in _get_response
    response = wrapped_callback(request, *callback_args, **callback_kwargs)
               ^^^^^^^^^^^^^^^^^^^^^^^^^^^^^^^^^^^^^^^^^^^^^^^^^^^^^^^^^^^^
  File "D:\OneDrive - Xcaliber Infotech\WORKSPACE\Products\Project-NAVY\navy\Lib\site-packages\django\views\decorators\csrf.py", line 65, in _view_wrapper
    return view_func(request, *args, **kwargs)
           ^^^^^^^^^^^^^^^^^^^^^^^^^^^^^^^^^^^
  File "D:\OneDrive - Xcaliber Infotech\WORKSPACE\Products\Project-NAVY\navy\Lib\site-packages\django\views\generic\base.py", line 105, in view
    return self.dispatch(request, *args, **kwargs)
           ^^^^^^^^^^^^^^^^^^^^^^^^^^^^^^^^^^^^^^^
  File "D:\OneDrive - Xcaliber Infotech\WORKSPACE\Products\Project-NAVY\navy\Lib\site-packages\rest_framework\views.py", line 515, in dispatch
    response = self.handle_exception(exc)
               ^^^^^^^^^^^^^^^^^^^^^^^^^^
  File "D:\OneDrive - Xcaliber Infotech\WORKSPACE\Products\Project-NAVY\navy\Lib\site-packages\rest_framework\views.py", line 475, in handle_exception
    self.raise_uncaught_exception(exc)
  File "D:\OneDrive - Xcaliber Infotech\WORKSPACE\Products\Project-NAVY\navy\Lib\site-packages\rest_framework\views.py", line 486, in raise_uncaught_exception
    raise exc
  File "D:\OneDrive - Xcaliber Infotech\WORKSPACE\Products\Project-NAVY\navy\Lib\site-packages\rest_framework\views.py", line 503, in dispatch
    self.initial(request, *args, **kwargs)
  File "D:\OneDrive - Xcaliber Infotech\WORKSPACE\Products\Project-NAVY\navy\Lib\site-packages\rest_framework\views.py", line 422, in initial
    self.check_throttles(request)
  File "D:\OneDrive - Xcaliber Infotech\WORKSPACE\Products\Project-NAVY\navy\Lib\site-packages\rest_framework\views.py", line 365, in check_throttles
    if not throttle.allow_request(request, self):
           ^^^^^^^^^^^^^^^^^^^^^^^^^^^^^^^^^^^^^
  File "D:\OneDrive - Xcaliber Infotech\WORKSPACE\Products\Project-NAVY\navy\Lib\site-packages\rest_framework\throttling.py", line 123, in allow_request
    self.history = self.cache.get(self.key, [])
                   ^^^^^^^^^^^^^^^^^^^^^^^^^^^^
  File "D:\OneDrive - Xcaliber Infotech\WORKSPACE\Products\Project-NAVY\navy\Lib\site-packages\django\core\cache\backends\redis.py", line 188, in get
    return self._cache.get(key, default)
           ^^^^^^^^^^^^^^^^^^^^^^^^^^^^^
  File "D:\OneDrive - Xcaliber Infotech\WORKSPACE\Products\Project-NAVY\navy\Lib\site-packages\django\core\cache\backends\redis.py", line 100, in get
    value = client.get(key)
            ^^^^^^^^^^^^^^^
  File "D:\OneDrive - Xcaliber Infotech\WORKSPACE\Products\Project-NAVY\navy\Lib\site-packages\redis\commands\core.py", line 1829, in get
    return self.execute_command("GET", name, keys=[name])
           ^^^^^^^^^^^^^^^^^^^^^^^^^^^^^^^^^^^^^^^^^^^^^^
  File "D:\OneDrive - Xcaliber Infotech\WORKSPACE\Products\Project-NAVY\navy\Lib\site-packages\redis\client.py", line 621, in execute_command
    return self._execute_command(*args, **options)
           ^^^^^^^^^^^^^^^^^^^^^^^^^^^^^^^^^^^^^^^
  File "D:\OneDrive - Xcaliber Infotech\WORKSPACE\Products\Project-NAVY\navy\Lib\site-packages\redis\client.py", line 627, in _execute_command
    conn = self.connection or pool.get_connection()
                              ^^^^^^^^^^^^^^^^^^^^^
  File "D:\OneDrive - Xcaliber Infotech\WORKSPACE\Products\Project-NAVY\navy\Lib\site-packages\redis\utils.py", line 195, in wrapper
    return func(*args, **kwargs)
           ^^^^^^^^^^^^^^^^^^^^^
  File "D:\OneDrive - Xcaliber Infotech\WORKSPACE\Products\Project-NAVY\navy\Lib\site-packages\redis\connection.py", line 1528, in get_connection
    connection = self.make_connection()
                 ^^^^^^^^^^^^^^^^^^^^^^
  File "D:\OneDrive - Xcaliber Infotech\WORKSPACE\Products\Project-NAVY\navy\Lib\site-packages\redis\connection.py", line 1574, in make_connection
    return self.connection_class(**self.connection_kwargs)
           ^^^^^^^^^^^^^^^^^^^^^^^^^^^^^^^^^^^^^^^^^^^^^^^
  File "D:\OneDrive - Xcaliber Infotech\WORKSPACE\Products\Project-NAVY\navy\Lib\site-packages\redis\connection.py", line 753, in __init__
    super().__init__(**kwargs)
TypeError: AbstractConnection.__init__() got an unexpected keyword argument 'CLIENT_CLASS'
ERROR 2025-08-15 18:23:19,475 basehttp 13388 42864 "POST /api/v1/auth/signup/ HTTP/1.1" 500 155239
WARNING 2025-08-15 18:24:32,592 log 13388 42864 Not Found: /auth/signup/
WARNING 2025-08-15 18:24:32,594 basehttp 13388 42864 "POST /auth/signup/ HTTP/1.1" 404 3031
WARNING 2025-08-15 18:24:54,627 log 13388 42864 Not Found: /auth/signup
WARNING 2025-08-15 18:24:54,628 basehttp 13388 42864 "POST /auth/signup HTTP/1.1" 404 3028
ERROR 2025-08-15 18:28:05,405 log 13388 42864 Internal Server Error: /api/v1/auth/signup
Traceback (most recent call last):
  File "D:\OneDrive - Xcaliber Infotech\WORKSPACE\Products\Project-NAVY\navy\Lib\site-packages\django\core\handlers\exception.py", line 55, in inner
    response = get_response(request)
               ^^^^^^^^^^^^^^^^^^^^^
  File "D:\OneDrive - Xcaliber Infotech\WORKSPACE\Products\Project-NAVY\navy\Lib\site-packages\django\utils\deprecation.py", line 122, in __call__
    response = self.process_response(request, response)
               ^^^^^^^^^^^^^^^^^^^^^^^^^^^^^^^^^^^^^^^^
  File "D:\OneDrive - Xcaliber Infotech\WORKSPACE\Products\Project-NAVY\navy\Lib\site-packages\django\middleware\common.py", line 108, in process_response
    return self.response_redirect_class(self.get_full_path_with_slash(request))
                                        ^^^^^^^^^^^^^^^^^^^^^^^^^^^^^^^^^^^^^^
  File "D:\OneDrive - Xcaliber Infotech\WORKSPACE\Products\Project-NAVY\navy\Lib\site-packages\django\middleware\common.py", line 87, in get_full_path_with_slash
    raise RuntimeError(
RuntimeError: You called this URL via POST, but the URL doesn't end in a slash and you have APPEND_SLASH set. Django can't redirect to the slash URL while maintaining POST data. Change your form to point to 127.0.0.1:8000/api/v1/auth/signup/ (note the trailing slash), or set APPEND_SLASH=False in your Django settings.
ERROR 2025-08-15 18:28:05,407 basehttp 13388 42864 "POST /api/v1/auth/signup HTTP/1.1" 500 76925
ERROR 2025-08-15 18:28:23,007 log 13388 41500 Internal Server Error: /api/v1/auth/signup/
Traceback (most recent call last):
  File "D:\OneDrive - Xcaliber Infotech\WORKSPACE\Products\Project-NAVY\navy\Lib\site-packages\redis\connection.py", line 1526, in get_connection
    connection = self._available_connections.pop()
                 ^^^^^^^^^^^^^^^^^^^^^^^^^^^^^^^^^
IndexError: pop from empty list

During handling of the above exception, another exception occurred:

Traceback (most recent call last):
  File "D:\OneDrive - Xcaliber Infotech\WORKSPACE\Products\Project-NAVY\navy\Lib\site-packages\django\core\handlers\exception.py", line 55, in inner
    response = get_response(request)
               ^^^^^^^^^^^^^^^^^^^^^
  File "D:\OneDrive - Xcaliber Infotech\WORKSPACE\Products\Project-NAVY\navy\Lib\site-packages\django\core\handlers\base.py", line 197, in _get_response
    response = wrapped_callback(request, *callback_args, **callback_kwargs)
               ^^^^^^^^^^^^^^^^^^^^^^^^^^^^^^^^^^^^^^^^^^^^^^^^^^^^^^^^^^^^
  File "D:\OneDrive - Xcaliber Infotech\WORKSPACE\Products\Project-NAVY\navy\Lib\site-packages\django\views\decorators\csrf.py", line 65, in _view_wrapper
    return view_func(request, *args, **kwargs)
           ^^^^^^^^^^^^^^^^^^^^^^^^^^^^^^^^^^^
  File "D:\OneDrive - Xcaliber Infotech\WORKSPACE\Products\Project-NAVY\navy\Lib\site-packages\django\views\generic\base.py", line 105, in view
    return self.dispatch(request, *args, **kwargs)
           ^^^^^^^^^^^^^^^^^^^^^^^^^^^^^^^^^^^^^^^
  File "D:\OneDrive - Xcaliber Infotech\WORKSPACE\Products\Project-NAVY\navy\Lib\site-packages\rest_framework\views.py", line 515, in dispatch
    response = self.handle_exception(exc)
               ^^^^^^^^^^^^^^^^^^^^^^^^^^
  File "D:\OneDrive - Xcaliber Infotech\WORKSPACE\Products\Project-NAVY\navy\Lib\site-packages\rest_framework\views.py", line 475, in handle_exception
    self.raise_uncaught_exception(exc)
  File "D:\OneDrive - Xcaliber Infotech\WORKSPACE\Products\Project-NAVY\navy\Lib\site-packages\rest_framework\views.py", line 486, in raise_uncaught_exception
    raise exc
  File "D:\OneDrive - Xcaliber Infotech\WORKSPACE\Products\Project-NAVY\navy\Lib\site-packages\rest_framework\views.py", line 503, in dispatch
    self.initial(request, *args, **kwargs)
  File "D:\OneDrive - Xcaliber Infotech\WORKSPACE\Products\Project-NAVY\navy\Lib\site-packages\rest_framework\views.py", line 422, in initial
    self.check_throttles(request)
  File "D:\OneDrive - Xcaliber Infotech\WORKSPACE\Products\Project-NAVY\navy\Lib\site-packages\rest_framework\views.py", line 365, in check_throttles
    if not throttle.allow_request(request, self):
           ^^^^^^^^^^^^^^^^^^^^^^^^^^^^^^^^^^^^^
  File "D:\OneDrive - Xcaliber Infotech\WORKSPACE\Products\Project-NAVY\navy\Lib\site-packages\rest_framework\throttling.py", line 123, in allow_request
    self.history = self.cache.get(self.key, [])
                   ^^^^^^^^^^^^^^^^^^^^^^^^^^^^
  File "D:\OneDrive - Xcaliber Infotech\WORKSPACE\Products\Project-NAVY\navy\Lib\site-packages\django\core\cache\backends\redis.py", line 188, in get
    return self._cache.get(key, default)
           ^^^^^^^^^^^^^^^^^^^^^^^^^^^^^
  File "D:\OneDrive - Xcaliber Infotech\WORKSPACE\Products\Project-NAVY\navy\Lib\site-packages\django\core\cache\backends\redis.py", line 100, in get
    value = client.get(key)
            ^^^^^^^^^^^^^^^
  File "D:\OneDrive - Xcaliber Infotech\WORKSPACE\Products\Project-NAVY\navy\Lib\site-packages\redis\commands\core.py", line 1829, in get
    return self.execute_command("GET", name, keys=[name])
           ^^^^^^^^^^^^^^^^^^^^^^^^^^^^^^^^^^^^^^^^^^^^^^
  File "D:\OneDrive - Xcaliber Infotech\WORKSPACE\Products\Project-NAVY\navy\Lib\site-packages\redis\client.py", line 621, in execute_command
    return self._execute_command(*args, **options)
           ^^^^^^^^^^^^^^^^^^^^^^^^^^^^^^^^^^^^^^^
  File "D:\OneDrive - Xcaliber Infotech\WORKSPACE\Products\Project-NAVY\navy\Lib\site-packages\redis\client.py", line 627, in _execute_command
    conn = self.connection or pool.get_connection()
                              ^^^^^^^^^^^^^^^^^^^^^
  File "D:\OneDrive - Xcaliber Infotech\WORKSPACE\Products\Project-NAVY\navy\Lib\site-packages\redis\utils.py", line 195, in wrapper
    return func(*args, **kwargs)
           ^^^^^^^^^^^^^^^^^^^^^
  File "D:\OneDrive - Xcaliber Infotech\WORKSPACE\Products\Project-NAVY\navy\Lib\site-packages\redis\connection.py", line 1528, in get_connection
    connection = self.make_connection()
                 ^^^^^^^^^^^^^^^^^^^^^^
  File "D:\OneDrive - Xcaliber Infotech\WORKSPACE\Products\Project-NAVY\navy\Lib\site-packages\redis\connection.py", line 1574, in make_connection
    return self.connection_class(**self.connection_kwargs)
           ^^^^^^^^^^^^^^^^^^^^^^^^^^^^^^^^^^^^^^^^^^^^^^^
  File "D:\OneDrive - Xcaliber Infotech\WORKSPACE\Products\Project-NAVY\navy\Lib\site-packages\redis\connection.py", line 753, in __init__
    super().__init__(**kwargs)
TypeError: AbstractConnection.__init__() got an unexpected keyword argument 'CLIENT_CLASS'
ERROR 2025-08-15 18:28:23,011 basehttp 13388 41500 "POST /api/v1/auth/signup/ HTTP/1.1" 500 155239
INFO 2025-08-15 18:32:09,748 autoreload 29132 21376 Watching for file changes with StatReloader
WARNING 2025-08-15 18:32:23,723 log 29132 43356 Not Found: /
WARNING 2025-08-15 18:32:23,725 basehttp 29132 43356 "GET / HTTP/1.1" 404 2976
WARNING 2025-08-15 18:32:33,652 log 29132 43356 Not Found: /api/v1/auth/
WARNING 2025-08-15 18:32:33,654 basehttp 29132 43356 "GET /api/v1/auth/ HTTP/1.1" 404 4224
ERROR 2025-08-15 18:32:47,869 log 29132 43356 Internal Server Error: /api/v1/auth/signup/
Traceback (most recent call last):
  File "D:\OneDrive - Xcaliber Infotech\WORKSPACE\Products\Project-NAVY\navy\Lib\site-packages\redis\connection.py", line 1526, in get_connection
    connection = self._available_connections.pop()
                 ^^^^^^^^^^^^^^^^^^^^^^^^^^^^^^^^^
IndexError: pop from empty list

During handling of the above exception, another exception occurred:

Traceback (most recent call last):
  File "D:\OneDrive - Xcaliber Infotech\WORKSPACE\Products\Project-NAVY\navy\Lib\site-packages\django\core\handlers\exception.py", line 55, in inner
    response = get_response(request)
               ^^^^^^^^^^^^^^^^^^^^^
  File "D:\OneDrive - Xcaliber Infotech\WORKSPACE\Products\Project-NAVY\navy\Lib\site-packages\django\core\handlers\base.py", line 197, in _get_response
    response = wrapped_callback(request, *callback_args, **callback_kwargs)
               ^^^^^^^^^^^^^^^^^^^^^^^^^^^^^^^^^^^^^^^^^^^^^^^^^^^^^^^^^^^^
  File "D:\OneDrive - Xcaliber Infotech\WORKSPACE\Products\Project-NAVY\navy\Lib\site-packages\django\views\decorators\csrf.py", line 65, in _view_wrapper
    return view_func(request, *args, **kwargs)
           ^^^^^^^^^^^^^^^^^^^^^^^^^^^^^^^^^^^
  File "D:\OneDrive - Xcaliber Infotech\WORKSPACE\Products\Project-NAVY\navy\Lib\site-packages\django\views\generic\base.py", line 105, in view
    return self.dispatch(request, *args, **kwargs)
           ^^^^^^^^^^^^^^^^^^^^^^^^^^^^^^^^^^^^^^^
  File "D:\OneDrive - Xcaliber Infotech\WORKSPACE\Products\Project-NAVY\navy\Lib\site-packages\rest_framework\views.py", line 515, in dispatch
    response = self.handle_exception(exc)
               ^^^^^^^^^^^^^^^^^^^^^^^^^^
  File "D:\OneDrive - Xcaliber Infotech\WORKSPACE\Products\Project-NAVY\navy\Lib\site-packages\rest_framework\views.py", line 475, in handle_exception
    self.raise_uncaught_exception(exc)
  File "D:\OneDrive - Xcaliber Infotech\WORKSPACE\Products\Project-NAVY\navy\Lib\site-packages\rest_framework\views.py", line 486, in raise_uncaught_exception
    raise exc
  File "D:\OneDrive - Xcaliber Infotech\WORKSPACE\Products\Project-NAVY\navy\Lib\site-packages\rest_framework\views.py", line 503, in dispatch
    self.initial(request, *args, **kwargs)
  File "D:\OneDrive - Xcaliber Infotech\WORKSPACE\Products\Project-NAVY\navy\Lib\site-packages\rest_framework\views.py", line 422, in initial
    self.check_throttles(request)
  File "D:\OneDrive - Xcaliber Infotech\WORKSPACE\Products\Project-NAVY\navy\Lib\site-packages\rest_framework\views.py", line 365, in check_throttles
    if not throttle.allow_request(request, self):
           ^^^^^^^^^^^^^^^^^^^^^^^^^^^^^^^^^^^^^
  File "D:\OneDrive - Xcaliber Infotech\WORKSPACE\Products\Project-NAVY\navy\Lib\site-packages\rest_framework\throttling.py", line 123, in allow_request
    self.history = self.cache.get(self.key, [])
                   ^^^^^^^^^^^^^^^^^^^^^^^^^^^^
  File "D:\OneDrive - Xcaliber Infotech\WORKSPACE\Products\Project-NAVY\navy\Lib\site-packages\django\core\cache\backends\redis.py", line 188, in get
    return self._cache.get(key, default)
           ^^^^^^^^^^^^^^^^^^^^^^^^^^^^^
  File "D:\OneDrive - Xcaliber Infotech\WORKSPACE\Products\Project-NAVY\navy\Lib\site-packages\django\core\cache\backends\redis.py", line 100, in get
    value = client.get(key)
            ^^^^^^^^^^^^^^^
  File "D:\OneDrive - Xcaliber Infotech\WORKSPACE\Products\Project-NAVY\navy\Lib\site-packages\redis\commands\core.py", line 1829, in get
    return self.execute_command("GET", name, keys=[name])
           ^^^^^^^^^^^^^^^^^^^^^^^^^^^^^^^^^^^^^^^^^^^^^^
  File "D:\OneDrive - Xcaliber Infotech\WORKSPACE\Products\Project-NAVY\navy\Lib\site-packages\redis\client.py", line 621, in execute_command
    return self._execute_command(*args, **options)
           ^^^^^^^^^^^^^^^^^^^^^^^^^^^^^^^^^^^^^^^
  File "D:\OneDrive - Xcaliber Infotech\WORKSPACE\Products\Project-NAVY\navy\Lib\site-packages\redis\client.py", line 627, in _execute_command
    conn = self.connection or pool.get_connection()
                              ^^^^^^^^^^^^^^^^^^^^^
  File "D:\OneDrive - Xcaliber Infotech\WORKSPACE\Products\Project-NAVY\navy\Lib\site-packages\redis\utils.py", line 195, in wrapper
    return func(*args, **kwargs)
           ^^^^^^^^^^^^^^^^^^^^^
  File "D:\OneDrive - Xcaliber Infotech\WORKSPACE\Products\Project-NAVY\navy\Lib\site-packages\redis\connection.py", line 1528, in get_connection
    connection = self.make_connection()
                 ^^^^^^^^^^^^^^^^^^^^^^
  File "D:\OneDrive - Xcaliber Infotech\WORKSPACE\Products\Project-NAVY\navy\Lib\site-packages\redis\connection.py", line 1574, in make_connection
    return self.connection_class(**self.connection_kwargs)
           ^^^^^^^^^^^^^^^^^^^^^^^^^^^^^^^^^^^^^^^^^^^^^^^
  File "D:\OneDrive - Xcaliber Infotech\WORKSPACE\Products\Project-NAVY\navy\Lib\site-packages\redis\connection.py", line 753, in __init__
    super().__init__(**kwargs)
TypeError: AbstractConnection.__init__() got an unexpected keyword argument 'CLIENT_CLASS'
ERROR 2025-08-15 18:32:47,922 basehttp 29132 43356 "GET /api/v1/auth/signup/ HTTP/1.1" 500 157327
INFO 2025-08-15 18:37:51,626 autoreload 29132 21376 D:\OneDrive - Xcaliber Infotech\WORKSPACE\Products\Project-NAVY\POC4\services\auth_service\backend\config\settings.py changed, reloading.
INFO 2025-08-15 18:37:53,699 autoreload 33160 10556 Watching for file changes with StatReloader
ERROR 2025-08-15 18:38:03,991 log 33160 30200 Internal Server Error: /api/v1/auth/signup/
Traceback (most recent call last):
  File "D:\OneDrive - Xcaliber Infotech\WORKSPACE\Products\Project-NAVY\navy\Lib\site-packages\redis\connection.py", line 389, in connect_check_health
    sock = self.retry.call_with_retry(
           ^^^^^^^^^^^^^^^^^^^^^^^^^^^
  File "D:\OneDrive - Xcaliber Infotech\WORKSPACE\Products\Project-NAVY\navy\Lib\site-packages\redis\retry.py", line 105, in call_with_retry
    return do()
           ^^^^
  File "D:\OneDrive - Xcaliber Infotech\WORKSPACE\Products\Project-NAVY\navy\Lib\site-packages\redis\connection.py", line 390, in <lambda>
    lambda: self._connect(), lambda error: self.disconnect(error)
            ^^^^^^^^^^^^^^^
  File "D:\OneDrive - Xcaliber Infotech\WORKSPACE\Products\Project-NAVY\navy\Lib\site-packages\redis\connection.py", line 803, in _connect
    raise err
  File "D:\OneDrive - Xcaliber Infotech\WORKSPACE\Products\Project-NAVY\navy\Lib\site-packages\redis\connection.py", line 787, in _connect
    sock.connect(socket_address)
ConnectionRefusedError: [WinError 10061] No connection could be made because the target machine actively refused it

During handling of the above exception, another exception occurred:

Traceback (most recent call last):
  File "D:\OneDrive - Xcaliber Infotech\WORKSPACE\Products\Project-NAVY\navy\Lib\site-packages\django\core\handlers\exception.py", line 55, in inner
    response = get_response(request)
               ^^^^^^^^^^^^^^^^^^^^^
  File "D:\OneDrive - Xcaliber Infotech\WORKSPACE\Products\Project-NAVY\navy\Lib\site-packages\django\core\handlers\base.py", line 197, in _get_response
    response = wrapped_callback(request, *callback_args, **callback_kwargs)
               ^^^^^^^^^^^^^^^^^^^^^^^^^^^^^^^^^^^^^^^^^^^^^^^^^^^^^^^^^^^^
  File "D:\OneDrive - Xcaliber Infotech\WORKSPACE\Products\Project-NAVY\navy\Lib\site-packages\django\views\decorators\csrf.py", line 65, in _view_wrapper
    return view_func(request, *args, **kwargs)
           ^^^^^^^^^^^^^^^^^^^^^^^^^^^^^^^^^^^
  File "D:\OneDrive - Xcaliber Infotech\WORKSPACE\Products\Project-NAVY\navy\Lib\site-packages\django\views\generic\base.py", line 105, in view
    return self.dispatch(request, *args, **kwargs)
           ^^^^^^^^^^^^^^^^^^^^^^^^^^^^^^^^^^^^^^^
  File "D:\OneDrive - Xcaliber Infotech\WORKSPACE\Products\Project-NAVY\navy\Lib\site-packages\rest_framework\views.py", line 515, in dispatch
    response = self.handle_exception(exc)
               ^^^^^^^^^^^^^^^^^^^^^^^^^^
  File "D:\OneDrive - Xcaliber Infotech\WORKSPACE\Products\Project-NAVY\navy\Lib\site-packages\rest_framework\views.py", line 475, in handle_exception
    self.raise_uncaught_exception(exc)
  File "D:\OneDrive - Xcaliber Infotech\WORKSPACE\Products\Project-NAVY\navy\Lib\site-packages\rest_framework\views.py", line 486, in raise_uncaught_exception
    raise exc
  File "D:\OneDrive - Xcaliber Infotech\WORKSPACE\Products\Project-NAVY\navy\Lib\site-packages\rest_framework\views.py", line 503, in dispatch
    self.initial(request, *args, **kwargs)
  File "D:\OneDrive - Xcaliber Infotech\WORKSPACE\Products\Project-NAVY\navy\Lib\site-packages\rest_framework\views.py", line 422, in initial
    self.check_throttles(request)
  File "D:\OneDrive - Xcaliber Infotech\WORKSPACE\Products\Project-NAVY\navy\Lib\site-packages\rest_framework\views.py", line 365, in check_throttles
    if not throttle.allow_request(request, self):
           ^^^^^^^^^^^^^^^^^^^^^^^^^^^^^^^^^^^^^
  File "D:\OneDrive - Xcaliber Infotech\WORKSPACE\Products\Project-NAVY\navy\Lib\site-packages\rest_framework\throttling.py", line 123, in allow_request
    self.history = self.cache.get(self.key, [])
                   ^^^^^^^^^^^^^^^^^^^^^^^^^^^^
  File "D:\OneDrive - Xcaliber Infotech\WORKSPACE\Products\Project-NAVY\navy\Lib\site-packages\django\core\cache\backends\redis.py", line 188, in get
    return self._cache.get(key, default)
           ^^^^^^^^^^^^^^^^^^^^^^^^^^^^^
  File "D:\OneDrive - Xcaliber Infotech\WORKSPACE\Products\Project-NAVY\navy\Lib\site-packages\django\core\cache\backends\redis.py", line 100, in get
    value = client.get(key)
            ^^^^^^^^^^^^^^^
  File "D:\OneDrive - Xcaliber Infotech\WORKSPACE\Products\Project-NAVY\navy\Lib\site-packages\redis\commands\core.py", line 1829, in get
    return self.execute_command("GET", name, keys=[name])
           ^^^^^^^^^^^^^^^^^^^^^^^^^^^^^^^^^^^^^^^^^^^^^^
  File "D:\OneDrive - Xcaliber Infotech\WORKSPACE\Products\Project-NAVY\navy\Lib\site-packages\redis\client.py", line 621, in execute_command
    return self._execute_command(*args, **options)
           ^^^^^^^^^^^^^^^^^^^^^^^^^^^^^^^^^^^^^^^
  File "D:\OneDrive - Xcaliber Infotech\WORKSPACE\Products\Project-NAVY\navy\Lib\site-packages\redis\client.py", line 627, in _execute_command
    conn = self.connection or pool.get_connection()
                              ^^^^^^^^^^^^^^^^^^^^^
  File "D:\OneDrive - Xcaliber Infotech\WORKSPACE\Products\Project-NAVY\navy\Lib\site-packages\redis\utils.py", line 195, in wrapper
    return func(*args, **kwargs)
           ^^^^^^^^^^^^^^^^^^^^^
  File "D:\OneDrive - Xcaliber Infotech\WORKSPACE\Products\Project-NAVY\navy\Lib\site-packages\redis\connection.py", line 1533, in get_connection
    connection.connect()
  File "D:\OneDrive - Xcaliber Infotech\WORKSPACE\Products\Project-NAVY\navy\Lib\site-packages\redis\connection.py", line 380, in connect
    self.connect_check_health(check_health=True)
  File "D:\OneDrive - Xcaliber Infotech\WORKSPACE\Products\Project-NAVY\navy\Lib\site-packages\redis\connection.py", line 397, in connect_check_health
    raise ConnectionError(self._error_message(e))
redis.exceptions.ConnectionError: Error 10061 connecting to localhost:6379. No connection could be made because the target machine actively refused it.
WARNING 2025-08-15 18:38:04,023 middleware 33160 30200 Slow request: POST /api/v1/auth/signup/ took 4.48s
ERROR 2025-08-15 18:38:04,028 basehttp 33160 30200 "POST /api/v1/auth/signup/ HTTP/1.1" 500 173037
INFO 2025-08-15 18:39:50,831 autoreload 9304 11736 Watching for file changes with StatReloader
ERROR 2025-08-15 18:40:13,996 log 9304 23060 Internal Server Error: /api/v1/auth/signup/
Traceback (most recent call last):
  File "D:\OneDrive - Xcaliber Infotech\WORKSPACE\Products\Project-NAVY\navy\Lib\site-packages\redis\connection.py", line 389, in connect_check_health
    sock = self.retry.call_with_retry(
           ^^^^^^^^^^^^^^^^^^^^^^^^^^^
  File "D:\OneDrive - Xcaliber Infotech\WORKSPACE\Products\Project-NAVY\navy\Lib\site-packages\redis\retry.py", line 105, in call_with_retry
    return do()
           ^^^^
  File "D:\OneDrive - Xcaliber Infotech\WORKSPACE\Products\Project-NAVY\navy\Lib\site-packages\redis\connection.py", line 390, in <lambda>
    lambda: self._connect(), lambda error: self.disconnect(error)
            ^^^^^^^^^^^^^^^
  File "D:\OneDrive - Xcaliber Infotech\WORKSPACE\Products\Project-NAVY\navy\Lib\site-packages\redis\connection.py", line 803, in _connect
    raise err
  File "D:\OneDrive - Xcaliber Infotech\WORKSPACE\Products\Project-NAVY\navy\Lib\site-packages\redis\connection.py", line 787, in _connect
    sock.connect(socket_address)
ConnectionRefusedError: [WinError 10061] No connection could be made because the target machine actively refused it

During handling of the above exception, another exception occurred:

Traceback (most recent call last):
  File "D:\OneDrive - Xcaliber Infotech\WORKSPACE\Products\Project-NAVY\navy\Lib\site-packages\django\core\handlers\exception.py", line 55, in inner
    response = get_response(request)
               ^^^^^^^^^^^^^^^^^^^^^
  File "D:\OneDrive - Xcaliber Infotech\WORKSPACE\Products\Project-NAVY\navy\Lib\site-packages\django\core\handlers\base.py", line 197, in _get_response
    response = wrapped_callback(request, *callback_args, **callback_kwargs)
               ^^^^^^^^^^^^^^^^^^^^^^^^^^^^^^^^^^^^^^^^^^^^^^^^^^^^^^^^^^^^
  File "D:\OneDrive - Xcaliber Infotech\WORKSPACE\Products\Project-NAVY\navy\Lib\site-packages\django\views\decorators\csrf.py", line 65, in _view_wrapper
    return view_func(request, *args, **kwargs)
           ^^^^^^^^^^^^^^^^^^^^^^^^^^^^^^^^^^^
  File "D:\OneDrive - Xcaliber Infotech\WORKSPACE\Products\Project-NAVY\navy\Lib\site-packages\django\views\generic\base.py", line 105, in view
    return self.dispatch(request, *args, **kwargs)
           ^^^^^^^^^^^^^^^^^^^^^^^^^^^^^^^^^^^^^^^
  File "D:\OneDrive - Xcaliber Infotech\WORKSPACE\Products\Project-NAVY\navy\Lib\site-packages\rest_framework\views.py", line 515, in dispatch
    response = self.handle_exception(exc)
               ^^^^^^^^^^^^^^^^^^^^^^^^^^
  File "D:\OneDrive - Xcaliber Infotech\WORKSPACE\Products\Project-NAVY\navy\Lib\site-packages\rest_framework\views.py", line 475, in handle_exception
    self.raise_uncaught_exception(exc)
  File "D:\OneDrive - Xcaliber Infotech\WORKSPACE\Products\Project-NAVY\navy\Lib\site-packages\rest_framework\views.py", line 486, in raise_uncaught_exception
    raise exc
  File "D:\OneDrive - Xcaliber Infotech\WORKSPACE\Products\Project-NAVY\navy\Lib\site-packages\rest_framework\views.py", line 503, in dispatch
    self.initial(request, *args, **kwargs)
  File "D:\OneDrive - Xcaliber Infotech\WORKSPACE\Products\Project-NAVY\navy\Lib\site-packages\rest_framework\views.py", line 422, in initial
    self.check_throttles(request)
  File "D:\OneDrive - Xcaliber Infotech\WORKSPACE\Products\Project-NAVY\navy\Lib\site-packages\rest_framework\views.py", line 365, in check_throttles
    if not throttle.allow_request(request, self):
           ^^^^^^^^^^^^^^^^^^^^^^^^^^^^^^^^^^^^^
  File "D:\OneDrive - Xcaliber Infotech\WORKSPACE\Products\Project-NAVY\navy\Lib\site-packages\rest_framework\throttling.py", line 123, in allow_request
    self.history = self.cache.get(self.key, [])
                   ^^^^^^^^^^^^^^^^^^^^^^^^^^^^
  File "D:\OneDrive - Xcaliber Infotech\WORKSPACE\Products\Project-NAVY\navy\Lib\site-packages\django\core\cache\backends\redis.py", line 188, in get
    return self._cache.get(key, default)
           ^^^^^^^^^^^^^^^^^^^^^^^^^^^^^
  File "D:\OneDrive - Xcaliber Infotech\WORKSPACE\Products\Project-NAVY\navy\Lib\site-packages\django\core\cache\backends\redis.py", line 100, in get
    value = client.get(key)
            ^^^^^^^^^^^^^^^
  File "D:\OneDrive - Xcaliber Infotech\WORKSPACE\Products\Project-NAVY\navy\Lib\site-packages\redis\commands\core.py", line 1829, in get
    return self.execute_command("GET", name, keys=[name])
           ^^^^^^^^^^^^^^^^^^^^^^^^^^^^^^^^^^^^^^^^^^^^^^
  File "D:\OneDrive - Xcaliber Infotech\WORKSPACE\Products\Project-NAVY\navy\Lib\site-packages\redis\client.py", line 621, in execute_command
    return self._execute_command(*args, **options)
           ^^^^^^^^^^^^^^^^^^^^^^^^^^^^^^^^^^^^^^^
  File "D:\OneDrive - Xcaliber Infotech\WORKSPACE\Products\Project-NAVY\navy\Lib\site-packages\redis\client.py", line 627, in _execute_command
    conn = self.connection or pool.get_connection()
                              ^^^^^^^^^^^^^^^^^^^^^
  File "D:\OneDrive - Xcaliber Infotech\WORKSPACE\Products\Project-NAVY\navy\Lib\site-packages\redis\utils.py", line 195, in wrapper
    return func(*args, **kwargs)
           ^^^^^^^^^^^^^^^^^^^^^
  File "D:\OneDrive - Xcaliber Infotech\WORKSPACE\Products\Project-NAVY\navy\Lib\site-packages\redis\connection.py", line 1533, in get_connection
    connection.connect()
  File "D:\OneDrive - Xcaliber Infotech\WORKSPACE\Products\Project-NAVY\navy\Lib\site-packages\redis\connection.py", line 380, in connect
    self.connect_check_health(check_health=True)
  File "D:\OneDrive - Xcaliber Infotech\WORKSPACE\Products\Project-NAVY\navy\Lib\site-packages\redis\connection.py", line 397, in connect_check_health
    raise ConnectionError(self._error_message(e))
redis.exceptions.ConnectionError: Error 10061 connecting to localhost:6379. No connection could be made because the target machine actively refused it.
WARNING 2025-08-15 18:40:14,028 middleware 9304 23060 Slow request: POST /api/v1/auth/signup/ took 4.52s
ERROR 2025-08-15 18:40:14,031 basehttp 9304 23060 "POST /api/v1/auth/signup/ HTTP/1.1" 500 173037
INFO 2025-08-15 18:49:56,602 autoreload 32228 3244 Watching for file changes with StatReloader
ERROR 2025-08-15 18:50:11,843 log 32228 21640 Internal Server Error: /api/v1/auth/signup/
Traceback (most recent call last):
  File "D:\OneDrive - Xcaliber Infotech\WORKSPACE\Products\Project-NAVY\navy\Lib\site-packages\redis\connection.py", line 389, in connect_check_health
    sock = self.retry.call_with_retry(
           ^^^^^^^^^^^^^^^^^^^^^^^^^^^
  File "D:\OneDrive - Xcaliber Infotech\WORKSPACE\Products\Project-NAVY\navy\Lib\site-packages\redis\retry.py", line 105, in call_with_retry
    return do()
           ^^^^
  File "D:\OneDrive - Xcaliber Infotech\WORKSPACE\Products\Project-NAVY\navy\Lib\site-packages\redis\connection.py", line 390, in <lambda>
    lambda: self._connect(), lambda error: self.disconnect(error)
            ^^^^^^^^^^^^^^^
  File "D:\OneDrive - Xcaliber Infotech\WORKSPACE\Products\Project-NAVY\navy\Lib\site-packages\redis\connection.py", line 803, in _connect
    raise err
  File "D:\OneDrive - Xcaliber Infotech\WORKSPACE\Products\Project-NAVY\navy\Lib\site-packages\redis\connection.py", line 787, in _connect
    sock.connect(socket_address)
ConnectionRefusedError: [WinError 10061] No connection could be made because the target machine actively refused it

During handling of the above exception, another exception occurred:

Traceback (most recent call last):
  File "D:\OneDrive - Xcaliber Infotech\WORKSPACE\Products\Project-NAVY\navy\Lib\site-packages\django\core\handlers\exception.py", line 55, in inner
    response = get_response(request)
               ^^^^^^^^^^^^^^^^^^^^^
  File "D:\OneDrive - Xcaliber Infotech\WORKSPACE\Products\Project-NAVY\navy\Lib\site-packages\django\core\handlers\base.py", line 197, in _get_response
    response = wrapped_callback(request, *callback_args, **callback_kwargs)
               ^^^^^^^^^^^^^^^^^^^^^^^^^^^^^^^^^^^^^^^^^^^^^^^^^^^^^^^^^^^^
  File "D:\OneDrive - Xcaliber Infotech\WORKSPACE\Products\Project-NAVY\navy\Lib\site-packages\django\views\decorators\csrf.py", line 65, in _view_wrapper
    return view_func(request, *args, **kwargs)
           ^^^^^^^^^^^^^^^^^^^^^^^^^^^^^^^^^^^
  File "D:\OneDrive - Xcaliber Infotech\WORKSPACE\Products\Project-NAVY\navy\Lib\site-packages\django\views\generic\base.py", line 105, in view
    return self.dispatch(request, *args, **kwargs)
           ^^^^^^^^^^^^^^^^^^^^^^^^^^^^^^^^^^^^^^^
  File "D:\OneDrive - Xcaliber Infotech\WORKSPACE\Products\Project-NAVY\navy\Lib\site-packages\rest_framework\views.py", line 515, in dispatch
    response = self.handle_exception(exc)
               ^^^^^^^^^^^^^^^^^^^^^^^^^^
  File "D:\OneDrive - Xcaliber Infotech\WORKSPACE\Products\Project-NAVY\navy\Lib\site-packages\rest_framework\views.py", line 475, in handle_exception
    self.raise_uncaught_exception(exc)
  File "D:\OneDrive - Xcaliber Infotech\WORKSPACE\Products\Project-NAVY\navy\Lib\site-packages\rest_framework\views.py", line 486, in raise_uncaught_exception
    raise exc
  File "D:\OneDrive - Xcaliber Infotech\WORKSPACE\Products\Project-NAVY\navy\Lib\site-packages\rest_framework\views.py", line 503, in dispatch
    self.initial(request, *args, **kwargs)
  File "D:\OneDrive - Xcaliber Infotech\WORKSPACE\Products\Project-NAVY\navy\Lib\site-packages\rest_framework\views.py", line 422, in initial
    self.check_throttles(request)
  File "D:\OneDrive - Xcaliber Infotech\WORKSPACE\Products\Project-NAVY\navy\Lib\site-packages\rest_framework\views.py", line 365, in check_throttles
    if not throttle.allow_request(request, self):
           ^^^^^^^^^^^^^^^^^^^^^^^^^^^^^^^^^^^^^
  File "D:\OneDrive - Xcaliber Infotech\WORKSPACE\Products\Project-NAVY\navy\Lib\site-packages\rest_framework\throttling.py", line 123, in allow_request
    self.history = self.cache.get(self.key, [])
                   ^^^^^^^^^^^^^^^^^^^^^^^^^^^^
  File "D:\OneDrive - Xcaliber Infotech\WORKSPACE\Products\Project-NAVY\navy\Lib\site-packages\django\core\cache\backends\redis.py", line 188, in get
    return self._cache.get(key, default)
           ^^^^^^^^^^^^^^^^^^^^^^^^^^^^^
  File "D:\OneDrive - Xcaliber Infotech\WORKSPACE\Products\Project-NAVY\navy\Lib\site-packages\django\core\cache\backends\redis.py", line 100, in get
    value = client.get(key)
            ^^^^^^^^^^^^^^^
  File "D:\OneDrive - Xcaliber Infotech\WORKSPACE\Products\Project-NAVY\navy\Lib\site-packages\redis\commands\core.py", line 1829, in get
    return self.execute_command("GET", name, keys=[name])
           ^^^^^^^^^^^^^^^^^^^^^^^^^^^^^^^^^^^^^^^^^^^^^^
  File "D:\OneDrive - Xcaliber Infotech\WORKSPACE\Products\Project-NAVY\navy\Lib\site-packages\redis\client.py", line 621, in execute_command
    return self._execute_command(*args, **options)
           ^^^^^^^^^^^^^^^^^^^^^^^^^^^^^^^^^^^^^^^
  File "D:\OneDrive - Xcaliber Infotech\WORKSPACE\Products\Project-NAVY\navy\Lib\site-packages\redis\client.py", line 627, in _execute_command
    conn = self.connection or pool.get_connection()
                              ^^^^^^^^^^^^^^^^^^^^^
  File "D:\OneDrive - Xcaliber Infotech\WORKSPACE\Products\Project-NAVY\navy\Lib\site-packages\redis\utils.py", line 195, in wrapper
    return func(*args, **kwargs)
           ^^^^^^^^^^^^^^^^^^^^^
  File "D:\OneDrive - Xcaliber Infotech\WORKSPACE\Products\Project-NAVY\navy\Lib\site-packages\redis\connection.py", line 1533, in get_connection
    connection.connect()
  File "D:\OneDrive - Xcaliber Infotech\WORKSPACE\Products\Project-NAVY\navy\Lib\site-packages\redis\connection.py", line 380, in connect
    self.connect_check_health(check_health=True)
  File "D:\OneDrive - Xcaliber Infotech\WORKSPACE\Products\Project-NAVY\navy\Lib\site-packages\redis\connection.py", line 397, in connect_check_health
    raise ConnectionError(self._error_message(e))
redis.exceptions.ConnectionError: Error 10061 connecting to localhost:6379. No connection could be made because the target machine actively refused it.
WARNING 2025-08-15 18:50:11,899 middleware 32228 21640 Slow request: POST /api/v1/auth/signup/ took 5.15s
ERROR 2025-08-15 18:50:11,903 basehttp 32228 21640 "POST /api/v1/auth/signup/ HTTP/1.1" 500 173037
INFO 2025-08-15 18:50:31,027 autoreload 32228 3244 D:\OneDrive - Xcaliber Infotech\WORKSPACE\Products\Project-NAVY\POC4\services\auth_service\backend\config\settings.py changed, reloading.
INFO 2025-08-15 18:50:33,494 autoreload 35144 2892 Watching for file changes with StatReloader
INFO 2025-08-15 18:50:40,013 views 35144 31984 User signup attempt from IP: 127.0.0.1
ERROR 2025-08-15 18:50:40,602 views 35144 31984 Unexpected error during signup from IP 127.0.0.1: no such table: user_profiles
ERROR 2025-08-15 18:50:40,607 log 35144 31984 Internal Server Error: /api/v1/auth/signup/
ERROR 2025-08-15 18:50:40,609 basehttp 35144 31984 "POST /api/v1/auth/signup/ HTTP/1.1" 500 132
WARNING 2025-08-15 18:58:59,208 log 35144 30892 Method Not Allowed: /api/v1/auth/signup/
WARNING 2025-08-15 18:58:59,209 basehttp 35144 30892 "GET /api/v1/auth/signup/ HTTP/1.1" 405 40
INFO 2025-08-15 18:59:09,900 views 35144 31984 User signup attempt from IP: 127.0.0.1
ERROR 2025-08-15 18:59:11,101 views 35144 31984 Unexpected error during signup from IP 127.0.0.1: no such table: user_profiles
WARNING 2025-08-15 18:59:11,104 middleware 35144 31984 Slow request: POST /api/v1/auth/signup/ took 1.21s
ERROR 2025-08-15 18:59:11,105 log 35144 31984 Internal Server Error: /api/v1/auth/signup/
ERROR 2025-08-15 18:59:11,108 basehttp 35144 31984 "POST /api/v1/auth/signup/ HTTP/1.1" 500 132
INFO 2025-08-15 19:01:30,605 views 35144 31984 User signup attempt from IP: 127.0.0.1
ERROR 2025-08-15 19:01:31,093 views 35144 31984 Unexpected error during signup from IP 127.0.0.1: no such table: user_profiles
ERROR 2025-08-15 19:01:31,094 log 35144 31984 Internal Server Error: /api/v1/auth/signup/
ERROR 2025-08-15 19:01:31,095 basehttp 35144 31984 "POST /api/v1/auth/signup/ HTTP/1.1" 500 132
INFO 2025-08-15 19:02:05,441 views 35144 31984 User signup attempt from IP: 127.0.0.1
ERROR 2025-08-15 19:02:06,271 views 35144 31984 Unexpected error during signup from IP 127.0.0.1: no such table: user_profiles
ERROR 2025-08-15 19:02:06,273 log 35144 31984 Internal Server Error: /api/v1/auth/signup/
ERROR 2025-08-15 19:02:06,274 basehttp 35144 31984 "POST /api/v1/auth/signup/ HTTP/1.1" 500 132
INFO 2025-08-15 19:03:03,963 autoreload 36780 39704 Watching for file changes with StatReloader
INFO 2025-08-15 19:03:16,957 autoreload 36780 39704 D:\OneDrive - Xcaliber Infotech\WORKSPACE\Products\Project-NAVY\POC4\services\auth_service\backend\config\settings.py changed, reloading.
INFO 2025-08-15 19:03:44,266 autoreload 26648 21732 Watching for file changes with StatReloader
ERROR 2025-08-15 19:04:04,234 log 26648 23928 Internal Server Error: /api/v1/auth/signup/
Traceback (most recent call last):
  File "D:\OneDrive - Xcaliber Infotech\WORKSPACE\Products\Project-NAVY\navy\Lib\site-packages\redis\connection.py", line 1526, in get_connection
    connection = self._available_connections.pop()
                 ^^^^^^^^^^^^^^^^^^^^^^^^^^^^^^^^^
IndexError: pop from empty list

During handling of the above exception, another exception occurred:

Traceback (most recent call last):
  File "D:\OneDrive - Xcaliber Infotech\WORKSPACE\Products\Project-NAVY\navy\Lib\site-packages\django\core\handlers\exception.py", line 55, in inner
    response = get_response(request)
               ^^^^^^^^^^^^^^^^^^^^^
  File "D:\OneDrive - Xcaliber Infotech\WORKSPACE\Products\Project-NAVY\navy\Lib\site-packages\django\core\handlers\base.py", line 197, in _get_response
    response = wrapped_callback(request, *callback_args, **callback_kwargs)
               ^^^^^^^^^^^^^^^^^^^^^^^^^^^^^^^^^^^^^^^^^^^^^^^^^^^^^^^^^^^^
  File "D:\OneDrive - Xcaliber Infotech\WORKSPACE\Products\Project-NAVY\navy\Lib\site-packages\django\views\decorators\csrf.py", line 65, in _view_wrapper
    return view_func(request, *args, **kwargs)
           ^^^^^^^^^^^^^^^^^^^^^^^^^^^^^^^^^^^
  File "D:\OneDrive - Xcaliber Infotech\WORKSPACE\Products\Project-NAVY\navy\Lib\site-packages\django\views\generic\base.py", line 105, in view
    return self.dispatch(request, *args, **kwargs)
           ^^^^^^^^^^^^^^^^^^^^^^^^^^^^^^^^^^^^^^^
  File "D:\OneDrive - Xcaliber Infotech\WORKSPACE\Products\Project-NAVY\navy\Lib\site-packages\rest_framework\views.py", line 515, in dispatch
    response = self.handle_exception(exc)
               ^^^^^^^^^^^^^^^^^^^^^^^^^^
  File "D:\OneDrive - Xcaliber Infotech\WORKSPACE\Products\Project-NAVY\navy\Lib\site-packages\rest_framework\views.py", line 475, in handle_exception
    self.raise_uncaught_exception(exc)
  File "D:\OneDrive - Xcaliber Infotech\WORKSPACE\Products\Project-NAVY\navy\Lib\site-packages\rest_framework\views.py", line 486, in raise_uncaught_exception
    raise exc
  File "D:\OneDrive - Xcaliber Infotech\WORKSPACE\Products\Project-NAVY\navy\Lib\site-packages\rest_framework\views.py", line 503, in dispatch
    self.initial(request, *args, **kwargs)
  File "D:\OneDrive - Xcaliber Infotech\WORKSPACE\Products\Project-NAVY\navy\Lib\site-packages\rest_framework\views.py", line 422, in initial
    self.check_throttles(request)
  File "D:\OneDrive - Xcaliber Infotech\WORKSPACE\Products\Project-NAVY\navy\Lib\site-packages\rest_framework\views.py", line 365, in check_throttles
    if not throttle.allow_request(request, self):
           ^^^^^^^^^^^^^^^^^^^^^^^^^^^^^^^^^^^^^
  File "D:\OneDrive - Xcaliber Infotech\WORKSPACE\Products\Project-NAVY\navy\Lib\site-packages\rest_framework\throttling.py", line 123, in allow_request
    self.history = self.cache.get(self.key, [])
                   ^^^^^^^^^^^^^^^^^^^^^^^^^^^^
  File "D:\OneDrive - Xcaliber Infotech\WORKSPACE\Products\Project-NAVY\navy\Lib\site-packages\django\core\cache\backends\redis.py", line 188, in get
    return self._cache.get(key, default)
           ^^^^^^^^^^^^^^^^^^^^^^^^^^^^^
  File "D:\OneDrive - Xcaliber Infotech\WORKSPACE\Products\Project-NAVY\navy\Lib\site-packages\django\core\cache\backends\redis.py", line 100, in get
    value = client.get(key)
            ^^^^^^^^^^^^^^^
  File "D:\OneDrive - Xcaliber Infotech\WORKSPACE\Products\Project-NAVY\navy\Lib\site-packages\redis\commands\core.py", line 1829, in get
    return self.execute_command("GET", name, keys=[name])
           ^^^^^^^^^^^^^^^^^^^^^^^^^^^^^^^^^^^^^^^^^^^^^^
  File "D:\OneDrive - Xcaliber Infotech\WORKSPACE\Products\Project-NAVY\navy\Lib\site-packages\redis\client.py", line 621, in execute_command
    return self._execute_command(*args, **options)
           ^^^^^^^^^^^^^^^^^^^^^^^^^^^^^^^^^^^^^^^
  File "D:\OneDrive - Xcaliber Infotech\WORKSPACE\Products\Project-NAVY\navy\Lib\site-packages\redis\client.py", line 627, in _execute_command
    conn = self.connection or pool.get_connection()
                              ^^^^^^^^^^^^^^^^^^^^^
  File "D:\OneDrive - Xcaliber Infotech\WORKSPACE\Products\Project-NAVY\navy\Lib\site-packages\redis\utils.py", line 195, in wrapper
    return func(*args, **kwargs)
           ^^^^^^^^^^^^^^^^^^^^^
  File "D:\OneDrive - Xcaliber Infotech\WORKSPACE\Products\Project-NAVY\navy\Lib\site-packages\redis\connection.py", line 1528, in get_connection
    connection = self.make_connection()
                 ^^^^^^^^^^^^^^^^^^^^^^
  File "D:\OneDrive - Xcaliber Infotech\WORKSPACE\Products\Project-NAVY\navy\Lib\site-packages\redis\connection.py", line 1574, in make_connection
    return self.connection_class(**self.connection_kwargs)
           ^^^^^^^^^^^^^^^^^^^^^^^^^^^^^^^^^^^^^^^^^^^^^^^
  File "D:\OneDrive - Xcaliber Infotech\WORKSPACE\Products\Project-NAVY\navy\Lib\site-packages\redis\connection.py", line 753, in __init__
    super().__init__(**kwargs)
TypeError: AbstractConnection.__init__() got an unexpected keyword argument 'CLIENT_CLASS'
ERROR 2025-08-15 19:04:04,255 basehttp 26648 23928 "POST /api/v1/auth/signup/ HTTP/1.1" 500 155258
INFO 2025-08-15 19:04:22,409 autoreload 26648 21732 D:\OneDrive - Xcaliber Infotech\WORKSPACE\Products\Project-NAVY\POC4\services\auth_service\backend\config\settings.py changed, reloading.
INFO 2025-08-15 19:04:24,374 autoreload 34492 29316 Watching for file changes with StatReloader
INFO 2025-08-15 19:04:39,441 autoreload 2772 36228 Watching for file changes with StatReloader
INFO 2025-08-15 19:05:01,932 views 2772 33236 User signup attempt from IP: 127.0.0.1
ERROR 2025-08-15 19:05:03,072 views 2772 33236 Unexpected error during signup from IP 127.0.0.1: no such table: user_profiles
WARNING 2025-08-15 19:05:03,073 middleware 2772 33236 Slow request: POST /api/v1/auth/signup/ took 1.16s
ERROR 2025-08-15 19:05:03,076 log 2772 33236 Internal Server Error: /api/v1/auth/signup/
ERROR 2025-08-15 19:05:03,078 basehttp 2772 33236 "POST /api/v1/auth/signup/ HTTP/1.1" 500 132
INFO 2025-08-15 19:18:40,067 autoreload 36120 36104 Watching for file changes with StatReloader
INFO 2025-08-15 19:19:58,344 autoreload 33880 42548 Watching for file changes with StatReloader
INFO 2025-08-15 19:21:31,336 autoreload 39296 34912 Watching for file changes with StatReloader
INFO 2025-08-15 19:21:47,623 views 39296 40396 User signup attempt from IP: 127.0.0.1
ERROR 2025-08-15 19:21:49,339 views 39296 40396 Unexpected error during signup from IP 127.0.0.1: relation "user_profiles" does not exist
LINE 1: INSERT INTO "user_profiles" ("id", "user_id", "rank", "unitn...
                    ^

WARNING 2025-08-15 19:21:49,343 middleware 39296 40396 Slow request: POST /api/v1/auth/signup/ took 1.73s
ERROR 2025-08-15 19:21:49,350 log 39296 40396 Internal Server Error: /api/v1/auth/signup/
ERROR 2025-08-15 19:21:49,353 basehttp 39296 40396 "POST /api/v1/auth/signup/ HTTP/1.1" 500 132
INFO 2025-08-15 19:23:06,626 autoreload 37800 34516 Watching for file changes with StatReloader
INFO 2025-08-15 19:23:13,207 views 37800 43996 User signup attempt from IP: 127.0.0.1
ERROR 2025-08-15 19:23:14,275 views 37800 43996 Unexpected error during signup from IP 127.0.0.1: column "id" of relation "user_profiles" does not exist
LINE 1: INSERT INTO "user_profiles" ("id", "user_id", "rank", "unitn...
                                     ^

WARNING 2025-08-15 19:23:14,275 middleware 37800 43996 Slow request: POST /api/v1/auth/signup/ took 1.08s
ERROR 2025-08-15 19:23:14,278 log 37800 43996 Internal Server Error: /api/v1/auth/signup/
ERROR 2025-08-15 19:23:14,279 basehttp 37800 43996 "POST /api/v1/auth/signup/ HTTP/1.1" 500 132
INFO 2025-08-15 19:25:43,541 autoreload 19680 30748 Watching for file changes with StatReloader
INFO 2025-08-15 19:25:56,320 views 19680 41064 User signup attempt from IP: 127.0.0.1
ERROR 2025-08-15 19:25:57,459 views 19680 41064 Unexpected error during signup from IP 127.0.0.1: column "id" of relation "user_profiles" does not exist
LINE 1: INSERT INTO "user_profiles" ("id", "user_id", "rank", "unitn...
                                     ^

WARNING 2025-08-15 19:25:57,460 middleware 19680 41064 Slow request: POST /api/v1/auth/signup/ took 1.15s
ERROR 2025-08-15 19:25:57,461 log 19680 41064 Internal Server Error: /api/v1/auth/signup/
ERROR 2025-08-15 19:25:57,462 basehttp 19680 41064 "POST /api/v1/auth/signup/ HTTP/1.1" 500 132
INFO 2025-08-15 19:26:54,995 autoreload 19152 37868 Watching for file changes with StatReloader
INFO 2025-08-15 19:27:16,109 views 19152 33236 User signup attempt from IP: 127.0.0.1
INFO 2025-08-15 19:27:17,108 serializers 19152 33236 New user created: ID 4, Profile: 7535a70d-e20b-4808-a6e4-93421bfd997f
INFO 2025-08-15 19:27:17,147 views 19152 33236 User signup successful: ID 4, Profile: 7535a70d-e20b-4808-a6e4-93421bfd997f from IP: 127.0.0.1
WARNING 2025-08-15 19:27:17,148 middleware 19152 33236 Slow request: POST /api/v1/auth/signup/ took 1.06s
INFO 2025-08-15 19:27:17,150 basehttp 19152 33236 "POST /api/v1/auth/signup/ HTTP/1.1" 201 360
INFO 2025-08-15 19:29:48,189 basehttp 19152 33236 "GET /api/v1/auth/profile HTTP/1.1" 301 0
WARNING 2025-08-15 19:29:48,207 log 19152 4356 Unauthorized: /api/v1/auth/profile/
WARNING 2025-08-15 19:29:48,207 basehttp 19152 4356 "GET /api/v1/auth/profile/ HTTP/1.1" 401 58
INFO 2025-08-15 19:31:54,228 serializers 19152 4356 Successful login for user ID: 4
INFO 2025-08-15 19:31:54,753 views 19152 4356 User ID 4 logged in successfully from IP: 127.0.0.1
WARNING 2025-08-15 19:31:54,777 middleware 19152 4356 Slow request: POST /api/v1/auth/login/ took 1.37s
INFO 2025-08-15 19:31:54,778 basehttp 19152 4356 "POST /api/v1/auth/login/ HTTP/1.1" 200 767
INFO 2025-08-15 19:32:29,520 basehttp 19152 4356 "GET /api/v1/auth/profile HTTP/1.1" 301 0
WARNING 2025-08-15 19:32:29,528 log 19152 38868 Unauthorized: /api/v1/auth/profile/
WARNING 2025-08-15 19:32:29,530 basehttp 19152 38868 "GET /api/v1/auth/profile/ HTTP/1.1" 401 58
INFO 2025-08-15 19:33:08,693 basehttp 19152 38868 "GET /api/v1/auth/profile HTTP/1.1" 301 0
WARNING 2025-08-15 19:33:08,698 log 19152 38708 Unauthorized: /api/v1/auth/profile/
WARNING 2025-08-15 19:33:08,699 basehttp 19152 38708 "GET /api/v1/auth/profile/ HTTP/1.1" 401 58
INFO 2025-08-15 19:33:33,976 basehttp 19152 38708 "GET /api/v1/auth/profile HTTP/1.1" 301 0
WARNING 2025-08-15 19:33:33,987 log 19152 43676 Unauthorized: /api/v1/auth/profile/
WARNING 2025-08-15 19:33:33,993 basehttp 19152 43676 "GET /api/v1/auth/profile/ HTTP/1.1" 401 172
INFO 2025-08-15 19:33:52,246 basehttp 19152 43676 "GET /api/v1/auth/profile HTTP/1.1" 301 0
INFO 2025-08-15 19:33:52,587 views 19152 42708 User ID 4 accessed profile
INFO 2025-08-15 19:33:52,592 basehttp 19152 42708 "GET /api/v1/auth/profile/ HTTP/1.1" 200 320
ERROR 2025-08-15 19:36:10,459 views 19152 42708 Unexpected error during logout: 'RefreshToken' object has no attribute 'blacklist'
ERROR 2025-08-15 19:36:10,460 log 19152 42708 Internal Server Error: /api/v1/auth/logout/
ERROR 2025-08-15 19:36:10,460 basehttp 19152 42708 "POST /api/v1/auth/logout/ HTTP/1.1" 500 127
INFO 2025-08-15 19:38:02,902 serializers 19152 42708 Successful login for user ID: 4
INFO 2025-08-15 19:38:03,024 views 19152 42708 User ID 4 logged in successfully from IP: 127.0.0.1
INFO 2025-08-15 19:38:03,026 basehttp 19152 42708 "POST /api/v1/auth/login/ HTTP/1.1" 200 767
ERROR 2025-08-15 19:38:59,350 views 19152 42708 Unexpected error during logout: 'RefreshToken' object has no attribute 'blacklist'
ERROR 2025-08-15 19:38:59,350 log 19152 42708 Internal Server Error: /api/v1/auth/logout/
ERROR 2025-08-15 19:38:59,351 basehttp 19152 42708 "POST /api/v1/auth/logout/ HTTP/1.1" 500 127
INFO 2025-08-15 19:42:52,539 autoreload 35232 37444 Watching for file changes with StatReloader
ERROR 2025-08-15 19:43:02,110 views 35232 22132 Unexpected error during logout: relation "token_blacklist_blacklistedtoken" does not exist
LINE 1: SELECT 1 AS "a" FROM "token_blacklist_blacklistedtoken" INNE...
                             ^

ERROR 2025-08-15 19:43:02,126 log 35232 22132 Internal Server Error: /api/v1/auth/logout/
ERROR 2025-08-15 19:43:02,129 basehttp 35232 22132 "POST /api/v1/auth/logout/ HTTP/1.1" 500 127
INFO 2025-08-15 19:43:49,476 autoreload 39156 34660 Watching for file changes with StatReloader
INFO 2025-08-15 19:43:56,954 views 39156 3144 User ID 4 logged out successfully
INFO 2025-08-15 19:43:56,956 basehttp 39156 3144 "POST /api/v1/auth/logout/ HTTP/1.1" 200 46
INFO 2025-08-15 20:08:55,495 autoreload 39156 34660 D:\OneDrive - Xcaliber Infotech\WORKSPACE\Products\Project-NAVY\POC4\services\auth_service\backend\apps\users\models.py changed, reloading.
INFO 2025-08-15 20:08:57,940 autoreload 28916 35900 Watching for file changes with StatReloader
INFO 2025-08-15 20:09:12,755 views 28916 42148 User signup attempt from IP: 127.0.0.1
WARNING 2025-08-15 20:09:13,296 views 28916 42148 Signup validation failed from IP 127.0.0.1
WARNING 2025-08-15 20:09:13,302 log 28916 42148 Bad Request: /api/v1/auth/signup/
WARNING 2025-08-15 20:09:13,304 basehttp 28916 42148 "POST /api/v1/auth/signup/ HTTP/1.1" 400 210
INFO 2025-08-15 20:09:47,882 autoreload 38056 31700 Watching for file changes with StatReloader
INFO 2025-08-15 20:09:53,261 views 38056 39580 User signup attempt from IP: 127.0.0.1
WARNING 2025-08-15 20:09:53,712 views 38056 39580 Signup validation failed from IP 127.0.0.1
WARNING 2025-08-15 20:09:53,720 log 38056 39580 Bad Request: /api/v1/auth/signup/
WARNING 2025-08-15 20:09:53,720 basehttp 38056 39580 "POST /api/v1/auth/signup/ HTTP/1.1" 400 210
INFO 2025-08-15 20:10:37,811 views 38056 39580 User signup attempt from IP: 127.0.0.1
ERROR 2025-08-15 20:10:38,540 views 38056 39580 Unexpected error during signup from IP 127.0.0.1: column "user_id" of relation "tbl_user_details" does not exist
LINE 1: INSERT INTO "tbl_user_details" ("id", "user_id", "rank", "un...
                                              ^

ERROR 2025-08-15 20:10:38,540 log 38056 39580 Internal Server Error: /api/v1/auth/signup/
ERROR 2025-08-15 20:10:38,540 basehttp 38056 39580 "POST /api/v1/auth/signup/ HTTP/1.1" 500 132
INFO 2025-08-17 18:26:47,786 autoreload 32916 27664 Watching for file changes with StatReloader
INFO 2025-08-17 18:27:15,412 serializers 32916 29408 Successful login for user ID: 4
INFO 2025-08-17 18:27:15,939 views 32916 29408 User ID 4 logged in successfully from IP: 127.0.0.1
WARNING 2025-08-17 18:27:15,964 middleware 32916 29408 Slow request: POST /api/v1/auth/login/ took 2.19s
INFO 2025-08-17 18:27:15,964 basehttp 32916 29408 "POST /api/v1/auth/login/ HTTP/1.1" 200 766
INFO 2025-08-17 18:27:29,144 basehttp 32916 29408 "GET /api/v1/auth/users/manage HTTP/1.1" 301 0
INFO 2025-08-17 18:27:29,741 basehttp 32916 38056 "GET /api/v1/auth/users/manage/ HTTP/1.1" 200 1186
INFO 2025-08-18 09:54:02,725 autoreload 32916 27664 D:\OneDrive - Xcaliber Infotech\WORKSPACE\Products\Project-NAVY\POC4-sumit\services\auth_service\backend\apps\users\models.py changed, reloading.
INFO 2025-08-18 09:54:17,938 autoreload 30636 14928 Watching for file changes with StatReloader
INFO 2025-08-18 14:40:52,080 autoreload 22984 30008 Watching for file changes with StatReloader
ERROR 2025-08-18 14:43:06,602 log 22984 26628 Internal Server Error: /api/v1/auth/feedback/
Traceback (most recent call last):
  File "C:\Users\sthombare\AppData\Local\Programs\Python\Python312\Lib\site-packages\django\db\backends\utils.py", line 105, in _execute
    return self.cursor.execute(sql, params)
           ^^^^^^^^^^^^^^^^^^^^^^^^^^^^^^^^
psycopg2.errors.InsufficientPrivilege: permission denied for table tbl_usermgmt_feedback


The above exception was the direct cause of the following exception:

Traceback (most recent call last):
  File "C:\Users\sthombare\AppData\Local\Programs\Python\Python312\Lib\site-packages\django\core\handlers\exception.py", line 55, in inner
    response = get_response(request)
               ^^^^^^^^^^^^^^^^^^^^^
  File "C:\Users\sthombare\AppData\Local\Programs\Python\Python312\Lib\site-packages\django\core\handlers\base.py", line 197, in _get_response
    response = wrapped_callback(request, *callback_args, **callback_kwargs)
               ^^^^^^^^^^^^^^^^^^^^^^^^^^^^^^^^^^^^^^^^^^^^^^^^^^^^^^^^^^^^
  File "C:\Users\sthombare\AppData\Local\Programs\Python\Python312\Lib\site-packages\django\views\decorators\csrf.py", line 65, in _view_wrapper
    return view_func(request, *args, **kwargs)
           ^^^^^^^^^^^^^^^^^^^^^^^^^^^^^^^^^^^
  File "C:\Users\sthombare\AppData\Local\Programs\Python\Python312\Lib\site-packages\django\views\generic\base.py", line 105, in view
    return self.dispatch(request, *args, **kwargs)
           ^^^^^^^^^^^^^^^^^^^^^^^^^^^^^^^^^^^^^^^
  File "C:\Users\sthombare\AppData\Local\Programs\Python\Python312\Lib\site-packages\rest_framework\views.py", line 515, in dispatch
    response = self.handle_exception(exc)
               ^^^^^^^^^^^^^^^^^^^^^^^^^^
  File "C:\Users\sthombare\AppData\Local\Programs\Python\Python312\Lib\site-packages\rest_framework\views.py", line 475, in handle_exception
    self.raise_uncaught_exception(exc)
  File "C:\Users\sthombare\AppData\Local\Programs\Python\Python312\Lib\site-packages\rest_framework\views.py", line 486, in raise_uncaught_exception
    raise exc
  File "C:\Users\sthombare\AppData\Local\Programs\Python\Python312\Lib\site-packages\rest_framework\views.py", line 512, in dispatch
    response = handler(request, *args, **kwargs)
               ^^^^^^^^^^^^^^^^^^^^^^^^^^^^^^^^^
  File "D:\Phoenix\Defense_POC\POC4\services\auth_service\backend\apps\users\views.py", line 780, in get
    return Response(serializer.data)
                    ^^^^^^^^^^^^^^^
  File "C:\Users\sthombare\AppData\Local\Programs\Python\Python312\Lib\site-packages\rest_framework\serializers.py", line 797, in data
    ret = super().data
          ^^^^^^^^^^^^
  File "C:\Users\sthombare\AppData\Local\Programs\Python\Python312\Lib\site-packages\rest_framework\serializers.py", line 251, in data
    self._data = self.to_representation(self.instance)
                 ^^^^^^^^^^^^^^^^^^^^^^^^^^^^^^^^^^^^^
  File "C:\Users\sthombare\AppData\Local\Programs\Python\Python312\Lib\site-packages\rest_framework\serializers.py", line 716, in to_representation
    self.child.to_representation(item) for item in iterable
                                                   ^^^^^^^^
  File "C:\Users\sthombare\AppData\Local\Programs\Python\Python312\Lib\site-packages\django\db\models\query.py", line 384, in __iter__
    self._fetch_all()
  File "C:\Users\sthombare\AppData\Local\Programs\Python\Python312\Lib\site-packages\django\db\models\query.py", line 1949, in _fetch_all
    self._result_cache = list(self._iterable_class(self))
                         ^^^^^^^^^^^^^^^^^^^^^^^^^^^^^^^^
  File "C:\Users\sthombare\AppData\Local\Programs\Python\Python312\Lib\site-packages\django\db\models\query.py", line 91, in __iter__
    results = compiler.execute_sql(
              ^^^^^^^^^^^^^^^^^^^^^
  File "C:\Users\sthombare\AppData\Local\Programs\Python\Python312\Lib\site-packages\django\db\models\sql\compiler.py", line 1623, in execute_sql
    cursor.execute(sql, params)
  File "C:\Users\sthombare\AppData\Local\Programs\Python\Python312\Lib\site-packages\django\db\backends\utils.py", line 122, in execute
    return super().execute(sql, params)
           ^^^^^^^^^^^^^^^^^^^^^^^^^^^^
  File "C:\Users\sthombare\AppData\Local\Programs\Python\Python312\Lib\site-packages\django\db\backends\utils.py", line 79, in execute
    return self._execute_with_wrappers(
           ^^^^^^^^^^^^^^^^^^^^^^^^^^^^
  File "C:\Users\sthombare\AppData\Local\Programs\Python\Python312\Lib\site-packages\django\db\backends\utils.py", line 92, in _execute_with_wrappers
    return executor(sql, params, many, context)
           ^^^^^^^^^^^^^^^^^^^^^^^^^^^^^^^^^^^^
  File "C:\Users\sthombare\AppData\Local\Programs\Python\Python312\Lib\site-packages\django\db\backends\utils.py", line 100, in _execute
    with self.db.wrap_database_errors:
         ^^^^^^^^^^^^^^^^^^^^^^^^^^^^
  File "C:\Users\sthombare\AppData\Local\Programs\Python\Python312\Lib\site-packages\django\db\utils.py", line 91, in __exit__
    raise dj_exc_value.with_traceback(traceback) from exc_value
  File "C:\Users\sthombare\AppData\Local\Programs\Python\Python312\Lib\site-packages\django\db\backends\utils.py", line 105, in _execute
    return self.cursor.execute(sql, params)
           ^^^^^^^^^^^^^^^^^^^^^^^^^^^^^^^^
django.db.utils.ProgrammingError: permission denied for table tbl_usermgmt_feedback

ERROR 2025-08-18 14:43:06,610 basehttp 22984 26628 "GET /api/v1/auth/feedback/ HTTP/1.1" 500 167344
ERROR 2025-08-18 14:43:48,349 log 22984 26628 Internal Server Error: /api/v1/auth/feedback/
Traceback (most recent call last):
  File "C:\Users\sthombare\AppData\Local\Programs\Python\Python312\Lib\site-packages\django\db\backends\utils.py", line 105, in _execute
    return self.cursor.execute(sql, params)
           ^^^^^^^^^^^^^^^^^^^^^^^^^^^^^^^^
psycopg2.errors.InsufficientPrivilege: permission denied for table tbl_usermgmt_feedback


The above exception was the direct cause of the following exception:

Traceback (most recent call last):
  File "C:\Users\sthombare\AppData\Local\Programs\Python\Python312\Lib\site-packages\django\core\handlers\exception.py", line 55, in inner
    response = get_response(request)
               ^^^^^^^^^^^^^^^^^^^^^
  File "C:\Users\sthombare\AppData\Local\Programs\Python\Python312\Lib\site-packages\django\core\handlers\base.py", line 197, in _get_response
    response = wrapped_callback(request, *callback_args, **callback_kwargs)
               ^^^^^^^^^^^^^^^^^^^^^^^^^^^^^^^^^^^^^^^^^^^^^^^^^^^^^^^^^^^^
  File "C:\Users\sthombare\AppData\Local\Programs\Python\Python312\Lib\site-packages\django\views\decorators\csrf.py", line 65, in _view_wrapper
    return view_func(request, *args, **kwargs)
           ^^^^^^^^^^^^^^^^^^^^^^^^^^^^^^^^^^^
  File "C:\Users\sthombare\AppData\Local\Programs\Python\Python312\Lib\site-packages\django\views\generic\base.py", line 105, in view
    return self.dispatch(request, *args, **kwargs)
           ^^^^^^^^^^^^^^^^^^^^^^^^^^^^^^^^^^^^^^^
  File "C:\Users\sthombare\AppData\Local\Programs\Python\Python312\Lib\site-packages\rest_framework\views.py", line 515, in dispatch
    response = self.handle_exception(exc)
               ^^^^^^^^^^^^^^^^^^^^^^^^^^
  File "C:\Users\sthombare\AppData\Local\Programs\Python\Python312\Lib\site-packages\rest_framework\views.py", line 475, in handle_exception
    self.raise_uncaught_exception(exc)
  File "C:\Users\sthombare\AppData\Local\Programs\Python\Python312\Lib\site-packages\rest_framework\views.py", line 486, in raise_uncaught_exception
    raise exc
  File "C:\Users\sthombare\AppData\Local\Programs\Python\Python312\Lib\site-packages\rest_framework\views.py", line 512, in dispatch
    response = handler(request, *args, **kwargs)
               ^^^^^^^^^^^^^^^^^^^^^^^^^^^^^^^^^
  File "D:\Phoenix\Defense_POC\POC4\services\auth_service\backend\apps\users\views.py", line 780, in get
    return Response(serializer.data)
                    ^^^^^^^^^^^^^^^
  File "C:\Users\sthombare\AppData\Local\Programs\Python\Python312\Lib\site-packages\rest_framework\serializers.py", line 797, in data
    ret = super().data
          ^^^^^^^^^^^^
  File "C:\Users\sthombare\AppData\Local\Programs\Python\Python312\Lib\site-packages\rest_framework\serializers.py", line 251, in data
    self._data = self.to_representation(self.instance)
                 ^^^^^^^^^^^^^^^^^^^^^^^^^^^^^^^^^^^^^
  File "C:\Users\sthombare\AppData\Local\Programs\Python\Python312\Lib\site-packages\rest_framework\serializers.py", line 716, in to_representation
    self.child.to_representation(item) for item in iterable
                                                   ^^^^^^^^
  File "C:\Users\sthombare\AppData\Local\Programs\Python\Python312\Lib\site-packages\django\db\models\query.py", line 384, in __iter__
    self._fetch_all()
  File "C:\Users\sthombare\AppData\Local\Programs\Python\Python312\Lib\site-packages\django\db\models\query.py", line 1949, in _fetch_all
    self._result_cache = list(self._iterable_class(self))
                         ^^^^^^^^^^^^^^^^^^^^^^^^^^^^^^^^
  File "C:\Users\sthombare\AppData\Local\Programs\Python\Python312\Lib\site-packages\django\db\models\query.py", line 91, in __iter__
    results = compiler.execute_sql(
              ^^^^^^^^^^^^^^^^^^^^^
  File "C:\Users\sthombare\AppData\Local\Programs\Python\Python312\Lib\site-packages\django\db\models\sql\compiler.py", line 1623, in execute_sql
    cursor.execute(sql, params)
  File "C:\Users\sthombare\AppData\Local\Programs\Python\Python312\Lib\site-packages\django\db\backends\utils.py", line 122, in execute
    return super().execute(sql, params)
           ^^^^^^^^^^^^^^^^^^^^^^^^^^^^
  File "C:\Users\sthombare\AppData\Local\Programs\Python\Python312\Lib\site-packages\django\db\backends\utils.py", line 79, in execute
    return self._execute_with_wrappers(
           ^^^^^^^^^^^^^^^^^^^^^^^^^^^^
  File "C:\Users\sthombare\AppData\Local\Programs\Python\Python312\Lib\site-packages\django\db\backends\utils.py", line 92, in _execute_with_wrappers
    return executor(sql, params, many, context)
           ^^^^^^^^^^^^^^^^^^^^^^^^^^^^^^^^^^^^
  File "C:\Users\sthombare\AppData\Local\Programs\Python\Python312\Lib\site-packages\django\db\backends\utils.py", line 100, in _execute
    with self.db.wrap_database_errors:
         ^^^^^^^^^^^^^^^^^^^^^^^^^^^^
  File "C:\Users\sthombare\AppData\Local\Programs\Python\Python312\Lib\site-packages\django\db\utils.py", line 91, in __exit__
    raise dj_exc_value.with_traceback(traceback) from exc_value
  File "C:\Users\sthombare\AppData\Local\Programs\Python\Python312\Lib\site-packages\django\db\backends\utils.py", line 105, in _execute
    return self.cursor.execute(sql, params)
           ^^^^^^^^^^^^^^^^^^^^^^^^^^^^^^^^
django.db.utils.ProgrammingError: permission denied for table tbl_usermgmt_feedback

ERROR 2025-08-18 14:43:48,351 basehttp 22984 26628 "GET /api/v1/auth/feedback/ HTTP/1.1" 500 167335
ERROR 2025-08-18 14:44:59,435 log 22984 25732 Internal Server Error: /api/v1/auth/feedback/
Traceback (most recent call last):
  File "C:\Users\sthombare\AppData\Local\Programs\Python\Python312\Lib\site-packages\django\db\backends\utils.py", line 105, in _execute
    return self.cursor.execute(sql, params)
           ^^^^^^^^^^^^^^^^^^^^^^^^^^^^^^^^
psycopg2.errors.InsufficientPrivilege: permission denied for table tbl_usermgmt_feedback


The above exception was the direct cause of the following exception:

Traceback (most recent call last):
  File "C:\Users\sthombare\AppData\Local\Programs\Python\Python312\Lib\site-packages\django\core\handlers\exception.py", line 55, in inner
    response = get_response(request)
               ^^^^^^^^^^^^^^^^^^^^^
  File "C:\Users\sthombare\AppData\Local\Programs\Python\Python312\Lib\site-packages\django\core\handlers\base.py", line 197, in _get_response
    response = wrapped_callback(request, *callback_args, **callback_kwargs)
               ^^^^^^^^^^^^^^^^^^^^^^^^^^^^^^^^^^^^^^^^^^^^^^^^^^^^^^^^^^^^
  File "C:\Users\sthombare\AppData\Local\Programs\Python\Python312\Lib\site-packages\django\views\decorators\csrf.py", line 65, in _view_wrapper
    return view_func(request, *args, **kwargs)
           ^^^^^^^^^^^^^^^^^^^^^^^^^^^^^^^^^^^
  File "C:\Users\sthombare\AppData\Local\Programs\Python\Python312\Lib\site-packages\django\views\generic\base.py", line 105, in view
    return self.dispatch(request, *args, **kwargs)
           ^^^^^^^^^^^^^^^^^^^^^^^^^^^^^^^^^^^^^^^
  File "C:\Users\sthombare\AppData\Local\Programs\Python\Python312\Lib\site-packages\rest_framework\views.py", line 515, in dispatch
    response = self.handle_exception(exc)
               ^^^^^^^^^^^^^^^^^^^^^^^^^^
  File "C:\Users\sthombare\AppData\Local\Programs\Python\Python312\Lib\site-packages\rest_framework\views.py", line 475, in handle_exception
    self.raise_uncaught_exception(exc)
  File "C:\Users\sthombare\AppData\Local\Programs\Python\Python312\Lib\site-packages\rest_framework\views.py", line 486, in raise_uncaught_exception
    raise exc
  File "C:\Users\sthombare\AppData\Local\Programs\Python\Python312\Lib\site-packages\rest_framework\views.py", line 512, in dispatch
    response = handler(request, *args, **kwargs)
               ^^^^^^^^^^^^^^^^^^^^^^^^^^^^^^^^^
  File "D:\Phoenix\Defense_POC\POC4\services\auth_service\backend\apps\users\views.py", line 780, in get
    return Response(serializer.data)
                    ^^^^^^^^^^^^^^^
  File "C:\Users\sthombare\AppData\Local\Programs\Python\Python312\Lib\site-packages\rest_framework\serializers.py", line 797, in data
    ret = super().data
          ^^^^^^^^^^^^
  File "C:\Users\sthombare\AppData\Local\Programs\Python\Python312\Lib\site-packages\rest_framework\serializers.py", line 251, in data
    self._data = self.to_representation(self.instance)
                 ^^^^^^^^^^^^^^^^^^^^^^^^^^^^^^^^^^^^^
  File "C:\Users\sthombare\AppData\Local\Programs\Python\Python312\Lib\site-packages\rest_framework\serializers.py", line 716, in to_representation
    self.child.to_representation(item) for item in iterable
                                                   ^^^^^^^^
  File "C:\Users\sthombare\AppData\Local\Programs\Python\Python312\Lib\site-packages\django\db\models\query.py", line 384, in __iter__
    self._fetch_all()
  File "C:\Users\sthombare\AppData\Local\Programs\Python\Python312\Lib\site-packages\django\db\models\query.py", line 1949, in _fetch_all
    self._result_cache = list(self._iterable_class(self))
                         ^^^^^^^^^^^^^^^^^^^^^^^^^^^^^^^^
  File "C:\Users\sthombare\AppData\Local\Programs\Python\Python312\Lib\site-packages\django\db\models\query.py", line 91, in __iter__
    results = compiler.execute_sql(
              ^^^^^^^^^^^^^^^^^^^^^
  File "C:\Users\sthombare\AppData\Local\Programs\Python\Python312\Lib\site-packages\django\db\models\sql\compiler.py", line 1623, in execute_sql
    cursor.execute(sql, params)
  File "C:\Users\sthombare\AppData\Local\Programs\Python\Python312\Lib\site-packages\django\db\backends\utils.py", line 122, in execute
    return super().execute(sql, params)
           ^^^^^^^^^^^^^^^^^^^^^^^^^^^^
  File "C:\Users\sthombare\AppData\Local\Programs\Python\Python312\Lib\site-packages\django\db\backends\utils.py", line 79, in execute
    return self._execute_with_wrappers(
           ^^^^^^^^^^^^^^^^^^^^^^^^^^^^
  File "C:\Users\sthombare\AppData\Local\Programs\Python\Python312\Lib\site-packages\django\db\backends\utils.py", line 92, in _execute_with_wrappers
    return executor(sql, params, many, context)
           ^^^^^^^^^^^^^^^^^^^^^^^^^^^^^^^^^^^^
  File "C:\Users\sthombare\AppData\Local\Programs\Python\Python312\Lib\site-packages\django\db\backends\utils.py", line 100, in _execute
    with self.db.wrap_database_errors:
         ^^^^^^^^^^^^^^^^^^^^^^^^^^^^
  File "C:\Users\sthombare\AppData\Local\Programs\Python\Python312\Lib\site-packages\django\db\utils.py", line 91, in __exit__
    raise dj_exc_value.with_traceback(traceback) from exc_value
  File "C:\Users\sthombare\AppData\Local\Programs\Python\Python312\Lib\site-packages\django\db\backends\utils.py", line 105, in _execute
    return self.cursor.execute(sql, params)
           ^^^^^^^^^^^^^^^^^^^^^^^^^^^^^^^^
django.db.utils.ProgrammingError: permission denied for table tbl_usermgmt_feedback

ERROR 2025-08-18 14:44:59,438 basehttp 22984 25732 "GET /api/v1/auth/feedback/ HTTP/1.1" 500 167335
INFO 2025-08-18 14:49:21,839 autoreload 28120 2760 Watching for file changes with StatReloader
INFO 2025-08-18 14:49:41,877 basehttp 28120 21872 "GET /api/v1/auth/feedback/ HTTP/1.1" 200 2693
INFO 2025-08-18 17:27:30,769 autoreload 19700 31192 Watching for file changes with StatReloader
INFO 2025-08-18 21:17:47,237 autoreload 31588 26168 Watching for file changes with StatReloader
WARNING 2025-08-18 21:54:45,459 serializers 31588 4348 Failed login attempt - invalid credentials
WARNING 2025-08-18 21:54:45,460 views 31588 4348 Failed login attempt from IP: 127.0.0.1
WARNING 2025-08-18 21:54:45,461 middleware 31588 4348 Slow request: POST /api/v1/auth/login/ took 1.41s
WARNING 2025-08-18 21:54:45,465 log 31588 4348 Bad Request: /api/v1/auth/login/
WARNING 2025-08-18 21:54:45,466 basehttp 31588 4348 "POST /api/v1/auth/login/ HTTP/1.1" 400 168
WARNING 2025-08-18 22:03:15,747 serializers 31588 4860 Failed login attempt - invalid credentials
WARNING 2025-08-18 22:03:15,748 views 31588 4860 Failed login attempt from IP: 127.0.0.1
WARNING 2025-08-18 22:03:15,749 middleware 31588 4860 Slow request: POST /api/v1/auth/login/ took 1.10s
WARNING 2025-08-18 22:03:15,751 log 31588 4860 Bad Request: /api/v1/auth/login/
WARNING 2025-08-18 22:03:15,752 basehttp 31588 4860 "POST /api/v1/auth/login/ HTTP/1.1" 400 168
INFO 2025-08-18 22:05:06,491 autoreload 14944 28444 Watching for file changes with StatReloader
WARNING 2025-08-19 11:32:17,535 serializers 14944 3632 Failed login attempt - invalid credentials
WARNING 2025-08-19 11:32:17,536 views 14944 3632 Failed login attempt from IP: 127.0.0.1
WARNING 2025-08-19 11:32:17,540 log 14944 3632 Bad Request: /api/v1/auth/login/
WARNING 2025-08-19 11:32:17,541 basehttp 14944 3632 "POST /api/v1/auth/login/ HTTP/1.1" 400 168
WARNING 2025-08-19 11:32:56,942 views 14944 3632 Failed login attempt from IP: 127.0.0.1
WARNING 2025-08-19 11:32:56,943 log 14944 3632 Bad Request: /api/v1/auth/login/
WARNING 2025-08-19 11:32:56,944 basehttp 14944 3632 "POST /api/v1/auth/login/ HTTP/1.1" 400 99
INFO 2025-08-19 11:39:31,199 autoreload 14944 28444 D:\Phoenix\Defense_POC\POC4\services\auth_service\backend\apps\users\serializers.py changed, reloading.
INFO 2025-08-19 11:39:38,524 autoreload 20976 30612 Watching for file changes with StatReloader
WARNING 2025-08-19 11:40:00,370 views 20976 31660 Failed login attempt from IP: 127.0.0.1
WARNING 2025-08-19 11:40:00,375 log 20976 31660 Bad Request: /api/v1/auth/login/
WARNING 2025-08-19 11:40:00,376 basehttp 20976 31660 "POST /api/v1/auth/login/ HTTP/1.1" 400 99
INFO 2025-08-19 11:44:56,499 autoreload 20976 30612 D:\Phoenix\Defense_POC\POC4\services\auth_service\backend\apps\users\views.py changed, reloading.
INFO 2025-08-19 11:45:01,460 autoreload 26184 27592 Watching for file changes with StatReloader
INFO 2025-08-19 11:45:15,005 autoreload 26184 27592 D:\Phoenix\Defense_POC\POC4\services\auth_service\backend\apps\users\models.py changed, reloading.
INFO 2025-08-19 11:45:20,031 autoreload 30540 9712 Watching for file changes with StatReloader
INFO 2025-08-19 12:35:46,876 autoreload 30540 9712 D:\Phoenix\Defense_POC\POC4\services\auth_service\backend\apps\users\models.py changed, reloading.
INFO 2025-08-19 12:35:51,922 autoreload 22084 30284 Watching for file changes with StatReloader
INFO 2025-08-19 12:36:47,031 autoreload 22084 30284 D:\Phoenix\Defense_POC\POC4\services\auth_service\backend\apps\users\views.py changed, reloading.
INFO 2025-08-19 12:36:52,129 autoreload 14940 26328 Watching for file changes with StatReloader
